Workbook

Sheet general_samples_p1
A1: Sample | B1: start_time | C1: end_time | D1: volume | E1: flow_rate | F1: pH | G1: EC | H1: no3- [mgN/L] | I1: CI_no3 | J1: no2_mmol_L | K1: so4_mg_L | L1: no3_mg_L | M1: obs
A2: P1T1 | B2: 45922.716 | C2: =B2+6/24 -> 45922.966 | D2: 18.91 | E2: =(D2-6.75)/6 -> 2.0266667 | K2: =VLOOKUP(A2,IC_raw!$C$2:$E$111,3,FALSE) -> #N/A | L2: =VLOOKUP(A2,IC_raw!$C$2:$E$111,2,FALSE) -> #N/A
A3: P1T2 | B3: =C2 -> 45922.966 | C3: =B3+6/24 -> 45923.216 | D3: 18.79 | E3: =(D3-6.75)/6 -> 2.0066667 | K3: =VLOOKUP(A3,IC_raw!$C$2:$E$111,3,FALSE) -> #N/A | L3: =VLOOKUP(A3,IC_raw!$C$2:$E$111,2,FALSE) -> #N/A
A4: P1T3 | B4: =C3 -> 45923.216 | C4: =B4+6/24 -> 45923.466 | D4: 18.81 | E4: =(D4-6.75)/6 -> 2.01 | F4: 8.25 | G4: 678 | H4: 13.5 | I4: =3/62*14 -> 0.67741935 | K4: =VLOOKUP(A4,IC_raw!$C$2:$E$111,3,FALSE) -> 0.99 | L4: =VLOOKUP(A4,IC_raw!$C$2:$E$111,2,FALSE) -> 65.01
A5: P1T4 | B5: =C4 -> 45923.466 | C5: =B5+6/24 -> 45923.716 | D5: 18.79 | E5: =(D5-6.75)/6 -> 2.0066667 | K5: =VLOOKUP(A5,IC_raw!$C$2:$E$111,3,FALSE) -> #N/A | L5: =VLOOKUP(A5,IC_raw!$C$2:$E$111,2,FALSE) -> #N/A
A6: P1T5 | B6: =C5 -> 45923.716 | C6: =B6+6/24 -> 45923.966 | D6: 18.3 | E6: =(D6-6.75)/6 -> 1.925 | K6: =VLOOKUP(A6,IC_raw!$C$2:$E$111,3,FALSE) -> #N/A | L6: =VLOOKUP(A6,IC_raw!$C$2:$E$111,2,FALSE) -> #N/A
A7: P1T6 | B7: =C6 -> 45923.966 | C7: =B7+6/24 -> 45924.216 | D7: 18.35 | E7: =(D7-6.75)/6 -> 1.9333333 | K7: =VLOOKUP(A7,IC_raw!$C$2:$E$111,3,FALSE) -> #N/A | L7: =VLOOKUP(A7,IC_raw!$C$2:$E$111,2,FALSE) -> #N/A
A8: P1T7 | B8: =C7 -> 45924.216 | C8: =B8+6/24 -> 45924.466 | D8: 18.55 | E8: =(D8-6.75)/6 -> 1.9666667 | K8: =VLOOKUP(A8,IC_raw!$C$2:$E$111,3,FALSE) -> #N/A | L8: =VLOOKUP(A8,IC_raw!$C$2:$E$111,2,FALSE) -> #N/A
A9: P1T8 | B9: =C8 -> 45924.466 | C9: =B9+6/24 -> 45924.716 | F9: 8.24 | G9: 596 | H9: 14.6 | I9: =3/62*14 -> 0.67741935 | K9: =VLOOKUP(A9,IC_raw!$C$2:$E$111,3,FALSE) -> 0.98 | L9: =VLOOKUP(A9,IC_raw!$C$2:$E$111,2,FALSE) -> 63.84
A10: P1T9 | B10: =C9 -> 45924.716 | C10: =B10+6/24 -> 45924.966 | D10: 18.52 | E10: =(D10-6.75)/6 -> 1.9616667 | K10: =VLOOKUP(A10,IC_raw!$C$2:$E$111,3,FALSE) -> #N/A | L10: =VLOOKUP(A10,IC_raw!$C$2:$E$111,2,FALSE) -> #N/A
A11: P1T10 | B11: =C10 -> 45924.966 | C11: =B11+6/24 -> 45925.216 | D11: 18.48 | E11: =(D11-6.75)/6 -> 1.955 | K11: =VLOOKUP(A11,IC_raw!$C$2:$E$111,3,FALSE) -> #N/A | L11: =VLOOKUP(A11,IC_raw!$C$2:$E$111,2,FALSE) -> #N/A
A12: P1T11 | B12: =C11 -> 45925.216 | C12: =B12+6/24 -> 45925.466 | D12: 18.33 | E12: =(D12-6.75)/6 -> 1.93 | K12: =VLOOKUP(A12,IC_raw!$C$2:$E$111,3,FALSE) -> #N/A | L12: =VLOOKUP(A12,IC_raw!$C$2:$E$111,2,FALSE) -> #N/A
A13: P1T12 | B13: =C12 -> 45925.466 | C13: =B13+6/24 -> 45925.716 | D13: 18.51 | E13: =(D13-6.75)/6 -> 1.96 | K13: =VLOOKUP(A13,IC_raw!$C$2:$E$111,3,FALSE) -> #N/A | L13: =VLOOKUP(A13,IC_raw!$C$2:$E$111,2,FALSE) -> #N/A | M13: *new calibration of pH EC
A14: P1T13 | B14: =C13 -> 45925.716 | C14: =B14+6/24 -> 45925.966 | D14: 18.18 | E14: =(D14-6.75)/6 -> 1.905 | K14: =VLOOKUP(A14,IC_raw!$C$2:$E$111,3,FALSE) -> #N/A | L14: =VLOOKUP(A14,IC_raw!$C$2:$E$111,2,FALSE) -> #N/A
A15: P1T14 | B15: =C14 -> 45925.966 | C15: =B15+6/24 -> 45926.216 | D15: 18.21 | E15: =(D15-6.75)/6 -> 1.91 | K15: =VLOOKUP(A15,IC_raw!$C$2:$E$111,3,FALSE) -> #N/A | L15: =VLOOKUP(A15,IC_raw!$C$2:$E$111,2,FALSE) -> #N/A
A16: P1T15 | B16: =C15 -> 45926.216 | C16: =B16+6/24 -> 45926.466 | D16: 18.27 | E16: =(D16-6.75)/6 -> 1.92 | F16: 8.21 | G16: 991 | H16: 14.4 | I16: =3/62*14 -> 0.67741935 | K16: =VLOOKUP(A16,IC_raw!$C$2:$E$111,3,FALSE) -> 0.96 | L16: =VLOOKUP(A16,IC_raw!$C$2:$E$111,2,FALSE) -> 62.62
A17: P1T16 | B17: =C16 -> 45926.466 | C17: =B17+6/24 -> 45926.716 | K17: =VLOOKUP(A17,IC_raw!$C$2:$E$111,3,FALSE) -> #N/A | L17: =VLOOKUP(A17,IC_raw!$C$2:$E$111,2,FALSE) -> #N/A | M17: * volume sample interrupted because of Fe sampling
A18: P1T17 | B18: =C17 -> 45926.716 | C18: =B18+6/24 -> 45926.966 | D18: 18.08 | E18: =(D18-6.75)/6 -> 1.8883333 | K18: =VLOOKUP(A18,IC_raw!$C$2:$E$111,3,FALSE) -> #N/A | L18: =VLOOKUP(A18,IC_raw!$C$2:$E$111,2,FALSE) -> #N/A
A19: P1T18 | B19: =C18 -> 45926.966 | C19: =B19+6/24 -> 45927.216 | D19: 18.12 | E19: =(D19-6.75)/6 -> 1.895 | K19: =VLOOKUP(A19,IC_raw!$C$2:$E$111,3,FALSE) -> #N/A | L19: =VLOOKUP(A19,IC_raw!$C$2:$E$111,2,FALSE) -> #N/A
A20: P1T19 | B20: =C19 -> 45927.216 | C20: =B20+6/24 -> 45927.466 | D20: 18.14 | E20: =(D20-6.75)/6 -> 1.8983333 | K20: =VLOOKUP(A20,IC_raw!$C$2:$E$111,3,FALSE) -> #N/A | L20: =VLOOKUP(A20,IC_raw!$C$2:$E$111,2,FALSE) -> #N/A
A21: P1T20 | B21: =C20 -> 45927.466 | C21: =B21+6/24 -> 45927.716 | D21: 18.22 | E21: =(D21-6.75)/6 -> 1.9116667 | K21: =VLOOKUP(A21,IC_raw!$C$2:$E$111,3,FALSE) -> #N/A | L21: =VLOOKUP(A21,IC_raw!$C$2:$E$111,2,FALSE) -> #N/A
A22: P1T21 | B22: =C21 -> 45927.716 | C22: =B22+6/24 -> 45927.966 | D22: 18.26 | E22: =(D22-6.75)/6 -> 1.9183333 | K22: =VLOOKUP(A22,IC_raw!$C$2:$E$111,3,FALSE) -> #N/A | L22: =VLOOKUP(A22,IC_raw!$C$2:$E$111,2,FALSE) -> #N/A
A23: P1T22 | B23: =C22 -> 45927.966 | C23: =B23+6/24 -> 45928.216 | D23: 18.2 | E23: =(D23-6.75)/6 -> 1.9083333 | K23: =VLOOKUP(A23,IC_raw!$C$2:$E$111,3,FALSE) -> #N/A | L23: =VLOOKUP(A23,IC_raw!$C$2:$E$111,2,FALSE) -> #N/A
A24: P1T23 | B24: =C23 -> 45928.216 | C24: =B24+6/24 -> 45928.466 | D24: 18.26 | E24: =(D24-6.75)/6 -> 1.9183333 | F24: 8.31 | G24: 852 | H24: 14 | I24: =3/62*14 -> 0.67741935 | K24: =VLOOKUP(A24,IC_raw!$C$2:$E$111,3,FALSE) -> 0.94 | L24: =VLOOKUP(A24,IC_raw!$C$2:$E$111,2,FALSE) -> 61.3
A25: P1T24 | B25: =C24 -> 45928.466 | C25: =B25+6/24 -> 45928.716 | D25: 18.35 | E25: =(D25-6.75)/6 -> 1.9333333 | K25: =VLOOKUP(A25,IC_raw!$C$2:$E$111,3,FALSE) -> #N/A | L25: =VLOOKUP(A25,IC_raw!$C$2:$E$111,2,FALSE) -> #N/A
A26: P1T25 | B26: =C25 -> 45928.716 | C26: =B26+6/24 -> 45928.966 | D26: 18.22 | E26: =(D26-6.75)/6 -> 1.9116667 | K26: =VLOOKUP(A26,IC_raw!$C$2:$E$111,3,FALSE) -> #N/A | L26: =VLOOKUP(A26,IC_raw!$C$2:$E$111,2,FALSE) -> #N/A
A27: P1T26 | B27: =C26 -> 45928.966 | C27: =B27+6/24 -> 45929.216 | D27: 18.29 | E27: =(D27-6.75)/6 -> 1.9233333 | K27: =VLOOKUP(A27,IC_raw!$C$2:$E$111,3,FALSE) -> #N/A | L27: =VLOOKUP(A27,IC_raw!$C$2:$E$111,2,FALSE) -> #N/A
A28: P1T27 | B28: =C27 -> 45929.216 | C28: =B28+6/24 -> 45929.466 | D28: 18.19 | E28: =(D28-6.75)/6 -> 1.9066667 | F28: 8.22 | G28: 924 | H28: 14.4 | I28: =3/62*14 -> 0.67741935 | K28: =VLOOKUP(A28,IC_raw!$C$2:$E$111,3,FALSE) -> 1.08 | L28: =VLOOKUP(A28,IC_raw!$C$2:$E$111,2,FALSE) -> 61.71 | M28: * cleaned pump tubing
A29: P1T28 | B29: =C28 -> 45929.466 | C29: =B29+6/24 -> 45929.716 | D29: 20.87 | E29: =(D29-6.75)/6 -> 2.3533333 | K29: =VLOOKUP(A29,IC_raw!$C$2:$E$111,3,FALSE) -> #N/A | L29: =VLOOKUP(A29,IC_raw!$C$2:$E$111,2,FALSE) -> #N/A
A30: P1T29 | B30: =C29 -> 45929.716 | C30: =B30+6/24 -> 45929.966 | D30: 20.44 | E30: =(D30-6.75)/6 -> 2.2816667 | K30: =VLOOKUP(A30,IC_raw!$C$2:$E$111,3,FALSE) -> #N/A | L30: =VLOOKUP(A30,IC_raw!$C$2:$E$111,2,FALSE) -> #N/A
A31: P1T30 | B31: =C30 -> 45929.966 | C31: =B31+6/24 -> 45930.216 | D31: 19.42 | E31: =(D31-6.75)/6 -> 2.1116667 | K31: =VLOOKUP(A31,IC_raw!$C$2:$E$111,3,FALSE) -> #N/A | L31: =VLOOKUP(A31,IC_raw!$C$2:$E$111,2,FALSE) -> #N/A
A32: P1T31 | B32: =C31 -> 45930.216 | C32: =B32+6/24 -> 45930.466 | D32: 19.97 | E32: =(D32-6.75)/6 -> 2.2033333 | K32: =VLOOKUP(A32,IC_raw!$C$2:$E$111,3,FALSE) -> #N/A | L32: =VLOOKUP(A32,IC_raw!$C$2:$E$111,2,FALSE) -> #N/A
A33: P1T32 | B33: =C32 -> 45930.466 | C33: =B33+6/24 -> 45930.716 | K33: =VLOOKUP(A33,IC_raw!$C$2:$E$111,3,FALSE) -> #N/A | L33: =VLOOKUP(A33,IC_raw!$C$2:$E$111,2,FALSE) -> #N/A
A34: P1T33 | B34: =C33 -> 45930.716 | C34: =B34+6/24 -> 45930.966 | D34: 19.61 | E34: =(D34-6.75)/6 -> 2.1433333 | K34: =VLOOKUP(A34,IC_raw!$C$2:$E$111,3,FALSE) -> #N/A | L34: =VLOOKUP(A34,IC_raw!$C$2:$E$111,2,FALSE) -> #N/A
A35: P1T34 | B35: =C34 -> 45930.966 | C35: =B35+6/24 -> 45931.216 | D35: 19.5 | E35: =(D35-6.75)/6 -> 2.125 | K35: =VLOOKUP(A35,IC_raw!$C$2:$E$111,3,FALSE) -> #N/A | L35: =VLOOKUP(A35,IC_raw!$C$2:$E$111,2,FALSE) -> #N/A
A36: P1T35 | B36: =C35 -> 45931.216 | C36: =B36+6/24 -> 45931.466 | D36: 19.39 | E36: =(D36-6.75)/6 -> 2.1066667 | F36: 8.14 | G36: 897 | H36: 18.1 | I36: =3/62*14 -> 0.67741935 | K36: =VLOOKUP(A36,IC_raw!$C$2:$E$111,3,FALSE) -> 0.95 | L36: =VLOOKUP(A36,IC_raw!$C$2:$E$111,2,FALSE) -> 81.28
A37: P1T36 | B37: =C36 -> 45931.466 | C37: =B37+6/24 -> 45931.716 | D37: 18.69 | E37: =(D37-6.75)/6 -> 1.99 | K37: =VLOOKUP(A37,IC_raw!$C$2:$E$111,3,FALSE) -> #N/A | L37: =VLOOKUP(A37,IC_raw!$C$2:$E$111,2,FALSE) -> #N/A
A38: P1T37 | B38: =C37 -> 45931.716 | C38: =B38+6/24 -> 45931.966 | D38: 18.61 | E38: =(D38-6.75)/6 -> 1.9766667 | K38: =VLOOKUP(A38,IC_raw!$C$2:$E$111,3,FALSE) -> #N/A | L38: =VLOOKUP(A38,IC_raw!$C$2:$E$111,2,FALSE) -> #N/A
A39: P1T38 | B39: =C38 -> 45931.966 | C39: =B39+6/24 -> 45932.216 | D39: 18.55 | E39: =(D39-6.75)/6 -> 1.9666667 | K39: =VLOOKUP(A39,IC_raw!$C$2:$E$111,3,FALSE) -> #N/A | L39: =VLOOKUP(A39,IC_raw!$C$2:$E$111,2,FALSE) -> #N/A
A40: P1T39 | B40: =C39 -> 45932.216 | C40: =B40+6/24 -> 45932.466 | D40: 18.52 | E40: =(D40-6.75)/6 -> 1.9616667 | F40: 8.22 | G40: 866 | H40: 18.1 | I40: =3/62*14 -> 0.67741935 | K40: =VLOOKUP(A40,IC_raw!$C$2:$E$111,3,FALSE) -> 0.94 | L40: =VLOOKUP(A40,IC_raw!$C$2:$E$111,2,FALSE) -> 75.97
...

Sheet general_samples_p2
A1: Sample | B1: start_time | C1: end_time | D1: volume | E1: flow_rate | F1: pH | G1: EC | H1: no3- [mgN/L] | I1: CI_no3 | J1: no2_mmol_L | K1: so4_mg_L | L1: no3_mg_L | M1: obs
A2: P2T1 | B2: 45922.716 | C2: =B2+6/24 -> 45922.966 | D2: 17.7 | E2: =(D2-6.75)/6 -> 1.825 | K2: =VLOOKUP(A2,IC_raw!$C$2:$E$111,3,FALSE) -> #N/A | L2: =VLOOKUP(A2,IC_raw!$C$2:$E$111,2,FALSE) -> #N/A
A3: P2T2 | B3: =C2 -> 45922.966 | C3: =B3+6/24 -> 45923.216 | D3: 16.89 | E3: =(D3-6.75)/6 -> 1.69 | K3: =VLOOKUP(A3,IC_raw!$C$2:$E$111,3,FALSE) -> #N/A | L3: =VLOOKUP(A3,IC_raw!$C$2:$E$111,2,FALSE) -> #N/A
A4: P2T3 | B4: =C3 -> 45923.216 | C4: =B4+6/24 -> 45923.466 | D4: 17.32 | E4: =(D4-6.75)/6 -> 1.7616667 | F4: 8.2 | G4: 699 | H4: 12.5 | I4: =3/62*14 -> 0.67741935 | K4: =VLOOKUP(A4,IC_raw!$C$2:$E$111,3,FALSE) -> #N/A | L4: =VLOOKUP(A4,IC_raw!$C$2:$E$111,2,FALSE) -> #N/A
A5: P2T4 | B5: =C4 -> 45923.466 | C5: =B5+6/24 -> 45923.716 | D5: 18.46 | E5: =(D5-6.75)/6 -> 1.9516667 | K5: =VLOOKUP(A5,IC_raw!$C$2:$E$111,3,FALSE) -> #N/A | L5: =VLOOKUP(A5,IC_raw!$C$2:$E$111,2,FALSE) -> #N/A
A6: P2T5 | B6: =C5 -> 45923.716 | C6: =B6+6/24 -> 45923.966 | D6: 19.52 | E6: =(D6-6.75)/6 -> 2.1283333 | K6: =VLOOKUP(A6,IC_raw!$C$2:$E$111,3,FALSE) -> #N/A | L6: =VLOOKUP(A6,IC_raw!$C$2:$E$111,2,FALSE) -> #N/A
A7: P2T6 | B7: =C6 -> 45923.966 | C7: =B7+6/24 -> 45924.216 | D7: 19.54 | E7: =(D7-6.75)/6 -> 2.1316667 | K7: =VLOOKUP(A7,IC_raw!$C$2:$E$111,3,FALSE) -> #N/A | L7: =VLOOKUP(A7,IC_raw!$C$2:$E$111,2,FALSE) -> #N/A
A8: P2T7 | B8: =C7 -> 45924.216 | C8: =B8+6/24 -> 45924.466 | D8: 19.64 | E8: =(D8-6.75)/6 -> 2.1483333 | K8: =VLOOKUP(A8,IC_raw!$C$2:$E$111,3,FALSE) -> #N/A | L8: =VLOOKUP(A8,IC_raw!$C$2:$E$111,2,FALSE) -> #N/A
A9: P2T8 | B9: =C8 -> 45924.466 | C9: =B9+6/24 -> 45924.716 | F9: 8.12 | G9: 641 | H9: 12.6 | I9: =3/62*14 -> 0.67741935 | K9: =VLOOKUP(A9,IC_raw!$C$2:$E$111,3,FALSE) -> 1.5 | L9: =VLOOKUP(A9,IC_raw!$C$2:$E$111,2,FALSE) -> 45.72
A10: P2T9 | B10: =C9 -> 45924.716 | C10: =B10+6/24 -> 45924.966 | D10: 19.37 | E10: =(D10-6.75)/6 -> 2.1033333 | K10: =VLOOKUP(A10,IC_raw!$C$2:$E$111,3,FALSE) -> #N/A | L10: =VLOOKUP(A10,IC_raw!$C$2:$E$111,2,FALSE) -> #N/A
A11: P2T10 | B11: =C10 -> 45924.966 | C11: =B11+6/24 -> 45925.216 | D11: 19.54 | E11: =(D11-6.75)/6 -> 2.1316667 | K11: =VLOOKUP(A11,IC_raw!$C$2:$E$111,3,FALSE) -> #N/A | L11: =VLOOKUP(A11,IC_raw!$C$2:$E$111,2,FALSE) -> #N/A
A12: P2T11 | B12: =C11 -> 45925.216 | C12: =B12+6/24 -> 45925.466 | D12: 19.56 | E12: =(D12-6.75)/6 -> 2.135 | K12: =VLOOKUP(A12,IC_raw!$C$2:$E$111,3,FALSE) -> #N/A | L12: =VLOOKUP(A12,IC_raw!$C$2:$E$111,2,FALSE) -> #N/A
A13: P2T12 | B13: =C12 -> 45925.466 | C13: =B13+6/24 -> 45925.716 | D13: 19.58 | E13: =(D13-6.75)/6 -> 2.1383333 | K13: =VLOOKUP(A13,IC_raw!$C$2:$E$111,3,FALSE) -> #N/A | L13: =VLOOKUP(A13,IC_raw!$C$2:$E$111,2,FALSE) -> #N/A
A14: P2T13 | B14: =C13 -> 45925.716 | C14: =B14+6/24 -> 45925.966 | D14: 19.39 | E14: =(D14-6.75)/6 -> 2.1066667 | K14: =VLOOKUP(A14,IC_raw!$C$2:$E$111,3,FALSE) -> #N/A | L14: =VLOOKUP(A14,IC_raw!$C$2:$E$111,2,FALSE) -> #N/A
A15: P2T14 | B15: =C14 -> 45925.966 | C15: =B15+6/24 -> 45926.216 | D15: 19.45 | E15: =(D15-6.75)/6 -> 2.1166667 | K15: =VLOOKUP(A15,IC_raw!$C$2:$E$111,3,FALSE) -> #N/A | L15: =VLOOKUP(A15,IC_raw!$C$2:$E$111,2,FALSE) -> #N/A
A16: P2T15 | B16: =C15 -> 45926.216 | C16: =B16+6/24 -> 45926.466 | D16: 19.43 | E16: =(D16-6.75)/6 -> 2.1133333 | F16: 8.09 | G16: 955 | H16: 14.1 | I16: =3/62*14 -> 0.67741935 | K16: =VLOOKUP(A16,IC_raw!$C$2:$E$111,3,FALSE) -> 1.26 | L16: =VLOOKUP(A16,IC_raw!$C$2:$E$111,2,FALSE) -> 57.3 | M16: *new calibration of pH EC
A17: P2T16 | B17: =C16 -> 45926.466 | C17: =B17+6/24 -> 45926.716 | K17: =VLOOKUP(A17,IC_raw!$C$2:$E$111,3,FALSE) -> #N/A | L17: =VLOOKUP(A17,IC_raw!$C$2:$E$111,2,FALSE) -> #N/A | M17: * volume sample interrupted because of Fe sampling
A18: P2T17 | B18: =C17 -> 45926.716 | C18: =B18+6/24 -> 45926.966 | D18: 18.87 | E18: =(D18-6.75)/6 -> 2.02 | K18: =VLOOKUP(A18,IC_raw!$C$2:$E$111,3,FALSE) -> #N/A | L18: =VLOOKUP(A18,IC_raw!$C$2:$E$111,2,FALSE) -> #N/A
A19: P2T18 | B19: =C18 -> 45926.966 | C19: =B19+6/24 -> 45927.216 | D19: 19.25 | E19: =(D19-6.75)/6 -> 2.0833333 | K19: =VLOOKUP(A19,IC_raw!$C$2:$E$111,3,FALSE) -> #N/A | L19: =VLOOKUP(A19,IC_raw!$C$2:$E$111,2,FALSE) -> #N/A
A20: P2T19 | B20: =C19 -> 45927.216 | C20: =B20+6/24 -> 45927.466 | D20: 19.21 | E20: =(D20-6.75)/6 -> 2.0766667 | K20: =VLOOKUP(A20,IC_raw!$C$2:$E$111,3,FALSE) -> #N/A | L20: =VLOOKUP(A20,IC_raw!$C$2:$E$111,2,FALSE) -> #N/A
A21: P2T20 | B21: =C20 -> 45927.466 | C21: =B21+6/24 -> 45927.716 | D21: 19.33 | E21: =(D21-6.75)/6 -> 2.0966667 | K21: =VLOOKUP(A21,IC_raw!$C$2:$E$111,3,FALSE) -> #N/A | L21: =VLOOKUP(A21,IC_raw!$C$2:$E$111,2,FALSE) -> #N/A
A22: P2T21 | B22: =C21 -> 45927.716 | C22: =B22+6/24 -> 45927.966 | D22: 19.35 | E22: =(D22-6.75)/6 -> 2.1 | K22: =VLOOKUP(A22,IC_raw!$C$2:$E$111,3,FALSE) -> #N/A | L22: =VLOOKUP(A22,IC_raw!$C$2:$E$111,2,FALSE) -> #N/A
A23: P2T22 | B23: =C22 -> 45927.966 | C23: =B23+6/24 -> 45928.216 | D23: 19.41 | E23: =(D23-6.75)/6 -> 2.11 | K23: =VLOOKUP(A23,IC_raw!$C$2:$E$111,3,FALSE) -> #N/A | L23: =VLOOKUP(A23,IC_raw!$C$2:$E$111,2,FALSE) -> #N/A
A24: P2T23 | B24: =C23 -> 45928.216 | C24: =B24+6/24 -> 45928.466 | D24: 19.33 | E24: =(D24-6.75)/6 -> 2.0966667 | F24: 8.25 | G24: 879 | H24: 13.2 | I24: =3/62*14 -> 0.67741935 | K24: =VLOOKUP(A24,IC_raw!$C$2:$E$111,3,FALSE) -> 1.17 | L24: =VLOOKUP(A24,IC_raw!$C$2:$E$111,2,FALSE) -> 54.81
A25: P2T24 | B25: =C24 -> 45928.466 | C25: =B25+6/24 -> 45928.716 | D25: 19.48 | E25: =(D25-6.75)/6 -> 2.1216667 | K25: =VLOOKUP(A25,IC_raw!$C$2:$E$111,3,FALSE) -> #N/A | L25: =VLOOKUP(A25,IC_raw!$C$2:$E$111,2,FALSE) -> #N/A
A26: P2T25 | B26: =C25 -> 45928.716 | C26: =B26+6/24 -> 45928.966 | D26: 19.4 | E26: =(D26-6.75)/6 -> 2.1083333 | K26: =VLOOKUP(A26,IC_raw!$C$2:$E$111,3,FALSE) -> #N/A | L26: =VLOOKUP(A26,IC_raw!$C$2:$E$111,2,FALSE) -> #N/A
A27: P2T26 | B27: =C26 -> 45928.966 | C27: =B27+6/24 -> 45929.216 | D27: 19.63 | E27: =(D27-6.75)/6 -> 2.1466667 | F27: 8.3 | G27: 846 | H27: 13.3 | I27: =3/62*14 -> 0.67741935 | K27: =VLOOKUP(A27,IC_raw!$C$2:$E$111,3,FALSE) -> #N/A | L27: =VLOOKUP(A27,IC_raw!$C$2:$E$111,2,FALSE) -> #N/A
A28: P2T27 | B28: =C27 -> 45929.216 | C28: =B28+6/24 -> 45929.466 | K28: =VLOOKUP(A28,IC_raw!$C$2:$E$111,3,FALSE) -> 1.2 | L28: =VLOOKUP(A28,IC_raw!$C$2:$E$111,2,FALSE) -> 56.33 | M28: * vial broke + cleaned pump tubing
A29: P2T28 | B29: =C28 -> 45929.466 | C29: =B29+6/24 -> 45929.716 | D29: 22.34 | E29: =(D29-6.75)/6 -> 2.5983333 | K29: =VLOOKUP(A29,IC_raw!$C$2:$E$111,3,FALSE) -> #N/A | L29: =VLOOKUP(A29,IC_raw!$C$2:$E$111,2,FALSE) -> #N/A
A30: P2T29 | B30: =C29 -> 45929.716 | C30: =B30+6/24 -> 45929.966 | D30: 21.75 | E30: =(D30-6.75)/6 -> 2.5 | K30: =VLOOKUP(A30,IC_raw!$C$2:$E$111,3,FALSE) -> #N/A | L30: =VLOOKUP(A30,IC_raw!$C$2:$E$111,2,FALSE) -> #N/A
A31: P2T30 | B31: =C30 -> 45929.966 | C31: =B31+6/24 -> 45930.216 | D31: 21.34 | E31: =(D31-6.75)/6 -> 2.4316667 | K31: =VLOOKUP(A31,IC_raw!$C$2:$E$111,3,FALSE) -> #N/A | L31: =VLOOKUP(A31,IC_raw!$C$2:$E$111,2,FALSE) -> #N/A
A32: P2T31 | B32: =C31 -> 45930.216 | C32: =B32+6/24 -> 45930.466 | D32: 20.98 | E32: =(D32-6.75)/6 -> 2.3716667 | K32: =VLOOKUP(A32,IC_raw!$C$2:$E$111,3,FALSE) -> #N/A | L32: =VLOOKUP(A32,IC_raw!$C$2:$E$111,2,FALSE) -> #N/A
A33: P2T32 | B33: =C32 -> 45930.466 | C33: =B33+6/24 -> 45930.716 | K33: =VLOOKUP(A33,IC_raw!$C$2:$E$111,3,FALSE) -> #N/A | L33: =VLOOKUP(A33,IC_raw!$C$2:$E$111,2,FALSE) -> #N/A
A34: P2T33 | B34: =C33 -> 45930.716 | C34: =B34+6/24 -> 45930.966 | D34: 18.44 | E34: =(D34-6.75)/6 -> 1.9483333 | K34: =VLOOKUP(A34,IC_raw!$C$2:$E$111,3,FALSE) -> #N/A | L34: =VLOOKUP(A34,IC_raw!$C$2:$E$111,2,FALSE) -> #N/A
A35: P2T34 | B35: =C34 -> 45930.966 | C35: =B35+6/24 -> 45931.216 | D35: 18.43 | E35: =(D35-6.75)/6 -> 1.9466667 | K35: =VLOOKUP(A35,IC_raw!$C$2:$E$111,3,FALSE) -> #N/A | L35: =VLOOKUP(A35,IC_raw!$C$2:$E$111,2,FALSE) -> #N/A
A36: P2T35 | B36: =C35 -> 45931.216 | C36: =B36+6/24 -> 45931.466 | D36: 18.27 | E36: =(D36-6.75)/6 -> 1.92 | F36: 7.95 | G36: 765 | H36: 13.7 | I36: =3/62*14 -> 0.67741935 | K36: =VLOOKUP(A36,IC_raw!$C$2:$E$111,3,FALSE) -> 1.27 | L36: =VLOOKUP(A36,IC_raw!$C$2:$E$111,2,FALSE) -> 63.49
A37: P2T36 | B37: =C36 -> 45931.466 | C37: =B37+6/24 -> 45931.716 | D37: 18.89 | E37: =(D37-6.75)/6 -> 2.0233333 | K37: =VLOOKUP(A37,IC_raw!$C$2:$E$111,3,FALSE) -> #N/A | L37: =VLOOKUP(A37,IC_raw!$C$2:$E$111,2,FALSE) -> #N/A
A38: P2T37 | B38: =C37 -> 45931.716 | C38: =B38+6/24 -> 45931.966 | D38: 18.7 | E38: =(D38-6.75)/6 -> 1.9916667 | K38: =VLOOKUP(A38,IC_raw!$C$2:$E$111,3,FALSE) -> #N/A | L38: =VLOOKUP(A38,IC_raw!$C$2:$E$111,2,FALSE) -> #N/A
A39: P2T38 | B39: =C38 -> 45931.966 | C39: =B39+6/24 -> 45932.216 | D39: 18.65 | E39: =(D39-6.75)/6 -> 1.9833333 | K39: =VLOOKUP(A39,IC_raw!$C$2:$E$111,3,FALSE) -> #N/A | L39: =VLOOKUP(A39,IC_raw!$C$2:$E$111,2,FALSE) -> #N/A
A40: P2T39 | B40: =C39 -> 45932.216 | C40: =B40+6/24 -> 45932.466 | D40: 18.64 | E40: =(D40-6.75)/6 -> 1.9816667 | F40: 8.21 | G40: 867 | H40: 14.2 | I40: =3/62*14 -> 0.67741935 | K40: =VLOOKUP(A40,IC_raw!$C$2:$E$111,3,FALSE) -> 1.21 | L40: =VLOOKUP(A40,IC_raw!$C$2:$E$111,2,FALSE) -> 59.62
...

Sheet general_samples_p3
A1: Sample | B1: start_time | C1: end_time | D1: volume | E1: flow_rate | F1: pH | G1: EC | H1: no3- [mgN/L] | I1: CI_no3 | J1: no2_mmol_L | K1: so4_mg_L | L1: no3_mg_L | M1: obs
A2: P3T1 | B2: 45922.716 | C2: =B2+6/24 -> 45922.966 | D2: 17.64 | E2: =(D2-6.75)/6 -> 1.815 | K2: =VLOOKUP(A2,IC_raw!$C$2:$E$111,3,FALSE) -> #N/A | L2: =VLOOKUP(A2,IC_raw!$C$2:$E$111,2,FALSE) -> #N/A
A3: P3T2 | B3: =C2 -> 45922.966 | C3: =B3+6/24 -> 45923.216 | D3: 17.88 | E3: =(D3-6.75)/6 -> 1.855 | K3: =VLOOKUP(A3,IC_raw!$C$2:$E$111,3,FALSE) -> #N/A | L3: =VLOOKUP(A3,IC_raw!$C$2:$E$111,2,FALSE) -> #N/A
A4: P3T3 | B4: =C3 -> 45923.216 | C4: =B4+6/24 -> 45923.466 | D4: 17.85 | E4: =(D4-6.75)/6 -> 1.85 | F4: 8.29 | G4: 773 | H4: 13.6 | I4: =3/62*14 -> 0.67741935 | K4: =VLOOKUP(A4,IC_raw!$C$2:$E$111,3,FALSE) -> 2.11 | L4: =VLOOKUP(A4,IC_raw!$C$2:$E$111,2,FALSE) -> 51.44
A5: P3T4 | B5: =C4 -> 45923.466 | C5: =B5+6/24 -> 45923.716 | D5: 18.5 | E5: =(D5-6.75)/6 -> 1.9583333 | K5: =VLOOKUP(A5,IC_raw!$C$2:$E$111,3,FALSE) -> #N/A | L5: =VLOOKUP(A5,IC_raw!$C$2:$E$111,2,FALSE) -> #N/A
A6: P3T5 | B6: =C5 -> 45923.716 | C6: =B6+6/24 -> 45923.966 | D6: 19.85 | E6: =(D6-6.75)/6 -> 2.1833333 | K6: =VLOOKUP(A6,IC_raw!$C$2:$E$111,3,FALSE) -> #N/A | L6: =VLOOKUP(A6,IC_raw!$C$2:$E$111,2,FALSE) -> #N/A
A7: P3T6 | B7: =C6 -> 45923.966 | C7: =B7+6/24 -> 45924.216 | D7: 19.76 | E7: =(D7-6.75)/6 -> 2.1683333 | K7: =VLOOKUP(A7,IC_raw!$C$2:$E$111,3,FALSE) -> #N/A | L7: =VLOOKUP(A7,IC_raw!$C$2:$E$111,2,FALSE) -> #N/A
A8: P3T7 | B8: =C7 -> 45924.216 | C8: =B8+6/24 -> 45924.466 | D8: 19.88 | E8: =(D8-6.75)/6 -> 2.1883333 | K8: =VLOOKUP(A8,IC_raw!$C$2:$E$111,3,FALSE) -> #N/A | L8: =VLOOKUP(A8,IC_raw!$C$2:$E$111,2,FALSE) -> #N/A
A9: P3T8 | B9: =C8 -> 45924.466 | C9: =B9+6/24 -> 45924.716 | F9: 8.12 | G9: 648 | H9: 14.2 | I9: =3/62*14 -> 0.67741935 | K9: =VLOOKUP(A9,IC_raw!$C$2:$E$111,3,FALSE) -> 1.66 | L9: =VLOOKUP(A9,IC_raw!$C$2:$E$111,2,FALSE) -> 51.9
A10: P3T9 | B10: =C9 -> 45924.716 | C10: =B10+6/24 -> 45924.966 | D10: 20.01 | E10: =(D10-6.75)/6 -> 2.21 | K10: =VLOOKUP(A10,IC_raw!$C$2:$E$111,3,FALSE) -> #N/A | L10: =VLOOKUP(A10,IC_raw!$C$2:$E$111,2,FALSE) -> #N/A
A11: P3T10 | B11: =C10 -> 45924.966 | C11: =B11+6/24 -> 45925.216 | D11: 19.77 | E11: =(D11-6.75)/6 -> 2.17 | K11: =VLOOKUP(A11,IC_raw!$C$2:$E$111,3,FALSE) -> #N/A | L11: =VLOOKUP(A11,IC_raw!$C$2:$E$111,2,FALSE) -> #N/A
A12: P3T11 | B12: =C11 -> 45925.216 | C12: =B12+6/24 -> 45925.466 | D12: 19.96 | E12: =(D12-6.75)/6 -> 2.2016667 | K12: =VLOOKUP(A12,IC_raw!$C$2:$E$111,3,FALSE) -> #N/A | L12: =VLOOKUP(A12,IC_raw!$C$2:$E$111,2,FALSE) -> #N/A
A13: P3T12 | B13: =C12 -> 45925.466 | C13: =B13+6/24 -> 45925.716 | D13: 20.1 | E13: =(D13-6.75)/6 -> 2.225 | K13: =VLOOKUP(A13,IC_raw!$C$2:$E$111,3,FALSE) -> #N/A | L13: =VLOOKUP(A13,IC_raw!$C$2:$E$111,2,FALSE) -> #N/A
A14: P3T13 | B14: =C13 -> 45925.716 | C14: =B14+6/24 -> 45925.966 | D14: 19.57 | E14: =(D14-6.75)/6 -> 2.1366667 | K14: =VLOOKUP(A14,IC_raw!$C$2:$E$111,3,FALSE) -> #N/A | L14: =VLOOKUP(A14,IC_raw!$C$2:$E$111,2,FALSE) -> #N/A
A15: P3T14 | B15: =C14 -> 45925.966 | C15: =B15+6/24 -> 45926.216 | D15: 19.86 | E15: =(D15-6.75)/6 -> 2.185 | K15: =VLOOKUP(A15,IC_raw!$C$2:$E$111,3,FALSE) -> #N/A | L15: =VLOOKUP(A15,IC_raw!$C$2:$E$111,2,FALSE) -> #N/A
A16: P3T15 | B16: =C15 -> 45926.216 | C16: =B16+6/24 -> 45926.466 | D16: 19.89 | E16: =(D16-6.75)/6 -> 2.19 | F16: 8.19 | G16: 878 | H16: 14 | I16: =3/62*14 -> 0.67741935 | K16: =VLOOKUP(A16,IC_raw!$C$2:$E$111,3,FALSE) -> 1.48 | L16: =VLOOKUP(A16,IC_raw!$C$2:$E$111,2,FALSE) -> 56.2 | M16: *new calibration of pH EC
A17: P3T16 | B17: =C16 -> 45926.466 | C17: =B17+6/24 -> 45926.716 | K17: =VLOOKUP(A17,IC_raw!$C$2:$E$111,3,FALSE) -> #N/A | L17: =VLOOKUP(A17,IC_raw!$C$2:$E$111,2,FALSE) -> #N/A | M17: * volume sample interrupted because of Fe sampling
A18: P3T17 | B18: =C17 -> 45926.716 | C18: =B18+6/24 -> 45926.966 | D18: 19.53 | E18: =(D18-6.75)/6 -> 2.13 | K18: =VLOOKUP(A18,IC_raw!$C$2:$E$111,3,FALSE) -> #N/A | L18: =VLOOKUP(A18,IC_raw!$C$2:$E$111,2,FALSE) -> #N/A
A19: P3T18 | B19: =C18 -> 45926.966 | C19: =B19+6/24 -> 45927.216 | D19: 19.51 | E19: =(D19-6.75)/6 -> 2.1266667 | K19: =VLOOKUP(A19,IC_raw!$C$2:$E$111,3,FALSE) -> #N/A | L19: =VLOOKUP(A19,IC_raw!$C$2:$E$111,2,FALSE) -> #N/A
A20: P3T19 | B20: =C19 -> 45927.216 | C20: =B20+6/24 -> 45927.466 | D20: 19.71 | E20: =(D20-6.75)/6 -> 2.16 | K20: =VLOOKUP(A20,IC_raw!$C$2:$E$111,3,FALSE) -> #N/A | L20: =VLOOKUP(A20,IC_raw!$C$2:$E$111,2,FALSE) -> #N/A
A21: P3T20 | B21: =C20 -> 45927.466 | C21: =B21+6/24 -> 45927.716 | D21: 19.45 | E21: =(D21-6.75)/6 -> 2.1166667 | K21: =VLOOKUP(A21,IC_raw!$C$2:$E$111,3,FALSE) -> #N/A | L21: =VLOOKUP(A21,IC_raw!$C$2:$E$111,2,FALSE) -> #N/A
A22: P3T21 | B22: =C21 -> 45927.716 | C22: =B22+6/24 -> 45927.966 | D22: 19.66 | E22: =(D22-6.75)/6 -> 2.1516667 | K22: =VLOOKUP(A22,IC_raw!$C$2:$E$111,3,FALSE) -> #N/A | L22: =VLOOKUP(A22,IC_raw!$C$2:$E$111,2,FALSE) -> #N/A
A23: P3T22 | B23: =C22 -> 45927.966 | C23: =B23+6/24 -> 45928.216 | D23: 19.86 | E23: =(D23-6.75)/6 -> 2.185 | K23: =VLOOKUP(A23,IC_raw!$C$2:$E$111,3,FALSE) -> #N/A | L23: =VLOOKUP(A23,IC_raw!$C$2:$E$111,2,FALSE) -> #N/A
A24: P3T23 | B24: =C23 -> 45928.216 | C24: =B24+6/24 -> 45928.466 | D24: 19.85 | E24: =(D24-6.75)/6 -> 2.1833333 | F24: 8.08 | G24: 905 | H24: 13.2 | I24: =3/62*14 -> 0.67741935 | K24: =VLOOKUP(A24,IC_raw!$C$2:$E$111,3,FALSE) -> 1.35 | L24: =VLOOKUP(A24,IC_raw!$C$2:$E$111,2,FALSE) -> 55.1
A25: P3T24 | B25: =C24 -> 45928.466 | C25: =B25+6/24 -> 45928.716 | D25: 19.88 | E25: =(D25-6.75)/6 -> 2.1883333 | K25: =VLOOKUP(A25,IC_raw!$C$2:$E$111,3,FALSE) -> #N/A | L25: =VLOOKUP(A25,IC_raw!$C$2:$E$111,2,FALSE) -> #N/A
A26: P3T25 | B26: =C25 -> 45928.716 | C26: =B26+6/24 -> 45928.966 | D26: 19.73 | E26: =(D26-6.75)/6 -> 2.1633333 | K26: =VLOOKUP(A26,IC_raw!$C$2:$E$111,3,FALSE) -> #N/A | L26: =VLOOKUP(A26,IC_raw!$C$2:$E$111,2,FALSE) -> #N/A
A27: P3T26 | B27: =C26 -> 45928.966 | C27: =B27+6/24 -> 45929.216 | D27: 19.77 | E27: =(D27-6.75)/6 -> 2.17 | K27: =VLOOKUP(A27,IC_raw!$C$2:$E$111,3,FALSE) -> #N/A | L27: =VLOOKUP(A27,IC_raw!$C$2:$E$111,2,FALSE) -> #N/A
A28: P3T27 | B28: =C27 -> 45929.216 | C28: =B28+6/24 -> 45929.466 | D28: 19.89 | E28: =(D28-6.75)/6 -> 2.19 | F28: 8.05 | G28: 872 | H28: 13.2 | I28: =3/62*14 -> 0.67741935 | K28: =VLOOKUP(A28,IC_raw!$C$2:$E$111,3,FALSE) -> 1.29 | L28: =VLOOKUP(A28,IC_raw!$C$2:$E$111,2,FALSE) -> 53.23 | M28: * cleaned pump tubing
A29: P3T28 | B29: =C28 -> 45929.466 | C29: =B29+6/24 -> 45929.716 | D29: 22.55 | E29: =(D29-6.75)/6 -> 2.6333333 | K29: =VLOOKUP(A29,IC_raw!$C$2:$E$111,3,FALSE) -> #N/A | L29: =VLOOKUP(A29,IC_raw!$C$2:$E$111,2,FALSE) -> #N/A
A30: P3T29 | B30: =C29 -> 45929.716 | C30: =B30+6/24 -> 45929.966 | D30: 22.41 | E30: =(D30-6.75)/6 -> 2.61 | K30: =VLOOKUP(A30,IC_raw!$C$2:$E$111,3,FALSE) -> #N/A | L30: =VLOOKUP(A30,IC_raw!$C$2:$E$111,2,FALSE) -> #N/A
A31: P3T30 | B31: =C30 -> 45929.966 | C31: =B31+6/24 -> 45930.216 | D31: 22.18 | E31: =(D31-6.75)/6 -> 2.5716667 | K31: =VLOOKUP(A31,IC_raw!$C$2:$E$111,3,FALSE) -> #N/A | L31: =VLOOKUP(A31,IC_raw!$C$2:$E$111,2,FALSE) -> #N/A
A32: P3T31 | B32: =C31 -> 45930.216 | C32: =B32+6/24 -> 45930.466 | D32: 21.67 | E32: =(D32-6.75)/6 -> 2.4866667 | K32: =VLOOKUP(A32,IC_raw!$C$2:$E$111,3,FALSE) -> #N/A | L32: =VLOOKUP(A32,IC_raw!$C$2:$E$111,2,FALSE) -> #N/A
A33: P3T32 | B33: =C32 -> 45930.466 | C33: =B33+6/24 -> 45930.716 | K33: =VLOOKUP(A33,IC_raw!$C$2:$E$111,3,FALSE) -> #N/A | L33: =VLOOKUP(A33,IC_raw!$C$2:$E$111,2,FALSE) -> #N/A
A34: P3T33 | B34: =C33 -> 45930.716 | C34: =B34+6/24 -> 45930.966 | D34: 19.86 | E34: =(D34-6.75)/6 -> 2.185 | K34: =VLOOKUP(A34,IC_raw!$C$2:$E$111,3,FALSE) -> #N/A | L34: =VLOOKUP(A34,IC_raw!$C$2:$E$111,2,FALSE) -> #N/A
A35: P3T34 | B35: =C34 -> 45930.966 | C35: =B35+6/24 -> 45931.216 | D35: 20.26 | E35: =(D35-6.75)/6 -> 2.2516667 | K35: =VLOOKUP(A35,IC_raw!$C$2:$E$111,3,FALSE) -> #N/A | L35: =VLOOKUP(A35,IC_raw!$C$2:$E$111,2,FALSE) -> #N/A
A36: P3T35 | B36: =C35 -> 45931.216 | C36: =B36+6/24 -> 45931.466 | D36: 19.84 | E36: =(D36-6.75)/6 -> 2.1816667 | F36: 7.96 | G36: 831 | H36: 14.7 | I36: =3/62*14 -> 0.67741935 | K36: =VLOOKUP(A36,IC_raw!$C$2:$E$111,3,FALSE) -> 1.25 | L36: =VLOOKUP(A36,IC_raw!$C$2:$E$111,2,FALSE) -> 67
A37: P3T36 | B37: =C36 -> 45931.466 | C37: =B37+6/24 -> 45931.716 | D37: 19.64 | E37: =(D37-6.75)/6 -> 2.1483333 | K37: =VLOOKUP(A37,IC_raw!$C$2:$E$111,3,FALSE) -> #N/A | L37: =VLOOKUP(A37,IC_raw!$C$2:$E$111,2,FALSE) -> #N/A
A38: P3T37 | B38: =C37 -> 45931.716 | C38: =B38+6/24 -> 45931.966 | D38: 19.37 | E38: =(D38-6.75)/6 -> 2.1033333 | K38: =VLOOKUP(A38,IC_raw!$C$2:$E$111,3,FALSE) -> #N/A | L38: =VLOOKUP(A38,IC_raw!$C$2:$E$111,2,FALSE) -> #N/A
A39: P3T38 | B39: =C38 -> 45931.966 | C39: =B39+6/24 -> 45932.216 | D39: 19.05 | E39: =(D39-6.75)/6 -> 2.05 | K39: =VLOOKUP(A39,IC_raw!$C$2:$E$111,3,FALSE) -> #N/A | L39: =VLOOKUP(A39,IC_raw!$C$2:$E$111,2,FALSE) -> #N/A
A40: P3T39 | B40: =C39 -> 45932.216 | C40: =B40+6/24 -> 45932.466 | D40: 19.28 | E40: =(D40-6.75)/6 -> 2.0883333 | F40: 8.06 | G40: 876 | H40: 14.4 | I40: =3/62*14 -> 0.67741935 | K40: =VLOOKUP(A40,IC_raw!$C$2:$E$111,3,FALSE) -> 1.23 | L40: =VLOOKUP(A40,IC_raw!$C$2:$E$111,2,FALSE) -> 60.19
...

Sheet general_samples_p4
A1: Sample | B1: start_time | C1: end_time | D1: volume | E1: flow_rate | F1: pH | G1: EC | H1: no3- [mgN/L] | I1: CI_no3 | J1: no2_mmol_L | K1: so4_mg_L | L1: no3_mg_L | M1: obs
A2: P4T1 | B2: 45922.716 | C2: =B2+6/24 -> 45922.966 | D2: 18.05 | E2: =(D2-6.75)/6 -> 1.8833333 | K2: =VLOOKUP(A2,IC_raw!$C$2:$E$111,3,FALSE) -> #N/A | L2: =VLOOKUP(A2,IC_raw!$C$2:$E$111,2,FALSE) -> #N/A
A3: P4T2 | B3: =C2 -> 45922.966 | C3: =B3+6/24 -> 45923.216 | D3: 17.12 | E3: =(D3-6.75)/6 -> 1.7283333 | K3: =VLOOKUP(A3,IC_raw!$C$2:$E$111,3,FALSE) -> #N/A | L3: =VLOOKUP(A3,IC_raw!$C$2:$E$111,2,FALSE) -> #N/A
A4: P4T3 | B4: =C3 -> 45923.216 | C4: =B4+6/24 -> 45923.466 | D4: 19.85 | E4: =(D4-6.75)/6 -> 2.1833333 | F4: 8.1 | G4: 473 | H4: 0.075 | I4: =0.5/62*14 -> 0.11290323 | K4: =VLOOKUP(A4,IC_raw!$C$2:$E$111,3,FALSE) -> 1.81 | L4: =VLOOKUP(A4,IC_raw!$C$2:$E$111,2,FALSE) -> 1.09
A5: P4T4 | B5: =C4 -> 45923.466 | C5: =B5+6/24 -> 45923.716 | D5: 20.21 | E5: =(D5-6.75)/6 -> 2.2433333 | K5: =VLOOKUP(A5,IC_raw!$C$2:$E$111,3,FALSE) -> #N/A | L5: =VLOOKUP(A5,IC_raw!$C$2:$E$111,2,FALSE) -> #N/A
A6: P4T5 | B6: =C5 -> 45923.716 | C6: =B6+6/24 -> 45923.966 | D6: 20.74 | E6: =(D6-6.75)/6 -> 2.3316667 | K6: =VLOOKUP(A6,IC_raw!$C$2:$E$111,3,FALSE) -> #N/A | L6: =VLOOKUP(A6,IC_raw!$C$2:$E$111,2,FALSE) -> #N/A
A7: P4T6 | B7: =C6 -> 45923.966 | C7: =B7+6/24 -> 45924.216 | D7: 20.36 | E7: =(D7-6.75)/6 -> 2.2683333 | K7: =VLOOKUP(A7,IC_raw!$C$2:$E$111,3,FALSE) -> #N/A | L7: =VLOOKUP(A7,IC_raw!$C$2:$E$111,2,FALSE) -> #N/A
A8: P4T7 | B8: =C7 -> 45924.216 | C8: =B8+6/24 -> 45924.466 | D8: 21.01 | E8: =(D8-6.75)/6 -> 2.3766667 | K8: =VLOOKUP(A8,IC_raw!$C$2:$E$111,3,FALSE) -> #N/A | L8: =VLOOKUP(A8,IC_raw!$C$2:$E$111,2,FALSE) -> #N/A
A9: P4T8 | B9: =C8 -> 45924.466 | C9: =B9+6/24 -> 45924.716 | F9: 7.98 | G9: 484 | H9: 0.04 | I9: =0.5/62*14 -> 0.11290323 | K9: =VLOOKUP(A9,IC_raw!$C$2:$E$111,3,FALSE) -> 1.54 | L9: =VLOOKUP(A9,IC_raw!$C$2:$E$111,2,FALSE) -> 1.02
A10: P4T9 | B10: =C9 -> 45924.716 | C10: =B10+6/24 -> 45924.966 | D10: 21.15 | E10: =(D10-6.75)/6 -> 2.4 | K10: =VLOOKUP(A10,IC_raw!$C$2:$E$111,3,FALSE) -> #N/A | L10: =VLOOKUP(A10,IC_raw!$C$2:$E$111,2,FALSE) -> #N/A
A11: P4T10 | B11: =C10 -> 45924.966 | C11: =B11+6/24 -> 45925.216 | D11: 20.98 | E11: =(D11-6.75)/6 -> 2.3716667 | K11: =VLOOKUP(A11,IC_raw!$C$2:$E$111,3,FALSE) -> #N/A | L11: =VLOOKUP(A11,IC_raw!$C$2:$E$111,2,FALSE) -> #N/A
A12: P4T11 | B12: =C11 -> 45925.216 | C12: =B12+6/24 -> 45925.466 | D12: 17.38 | E12: =(D12-6.75)/6 -> 1.7716667 | K12: =VLOOKUP(A12,IC_raw!$C$2:$E$111,3,FALSE) -> #N/A | L12: =VLOOKUP(A12,IC_raw!$C$2:$E$111,2,FALSE) -> #N/A
A13: P4T12 | B13: =C12 -> 45925.466 | C13: =B13+6/24 -> 45925.716 | D13: 21.34 | E13: =(D13-6.75)/6 -> 2.4316667 | K13: =VLOOKUP(A13,IC_raw!$C$2:$E$111,3,FALSE) -> #N/A | L13: =VLOOKUP(A13,IC_raw!$C$2:$E$111,2,FALSE) -> #N/A
A14: P4T13 | B14: =C13 -> 45925.716 | C14: =B14+6/24 -> 45925.966 | D14: 21.16 | E14: =(D14-6.75)/6 -> 2.4016667 | K14: =VLOOKUP(A14,IC_raw!$C$2:$E$111,3,FALSE) -> #N/A | L14: =VLOOKUP(A14,IC_raw!$C$2:$E$111,2,FALSE) -> #N/A
A15: P4T14 | B15: =C14 -> 45925.966 | C15: =B15+6/24 -> 45926.216 | D15: 21.19 | E15: =(D15-6.75)/6 -> 2.4066667 | K15: =VLOOKUP(A15,IC_raw!$C$2:$E$111,3,FALSE) -> #N/A | L15: =VLOOKUP(A15,IC_raw!$C$2:$E$111,2,FALSE) -> #N/A
A16: P4T15 | B16: =C15 -> 45926.216 | C16: =B16+6/24 -> 45926.466 | D16: 21.3 | E16: =(D16-6.75)/6 -> 2.425 | F16: 7.88 | G16: 621 | H16: 0.047 | I16: =0.5/62*14 -> 0.11290323 | K16: =VLOOKUP(A16,IC_raw!$C$2:$E$111,3,FALSE) -> 1.21 | L16: =VLOOKUP(A16,IC_raw!$C$2:$E$111,2,FALSE) -> 1 | M16: *new calibration of pH EC
A17: P4T16 | B17: =C16 -> 45926.466 | C17: =B17+6/24 -> 45926.716 | K17: =VLOOKUP(A17,IC_raw!$C$2:$E$111,3,FALSE) -> #N/A | L17: =VLOOKUP(A17,IC_raw!$C$2:$E$111,2,FALSE) -> #N/A | M17: * volume sample interrupted because of Fe sampling
A18: P4T17 | B18: =C17 -> 45926.716 | C18: =B18+6/24 -> 45926.966 | D18: 20.8 | E18: =(D18-6.75)/6 -> 2.3416667 | K18: =VLOOKUP(A18,IC_raw!$C$2:$E$111,3,FALSE) -> #N/A | L18: =VLOOKUP(A18,IC_raw!$C$2:$E$111,2,FALSE) -> #N/A
A19: P4T18 | B19: =C18 -> 45926.966 | C19: =B19+6/24 -> 45927.216 | D19: 21.05 | E19: =(D19-6.75)/6 -> 2.3833333 | K19: =VLOOKUP(A19,IC_raw!$C$2:$E$111,3,FALSE) -> #N/A | L19: =VLOOKUP(A19,IC_raw!$C$2:$E$111,2,FALSE) -> #N/A
A20: P4T19 | B20: =C19 -> 45927.216 | C20: =B20+6/24 -> 45927.466 | D20: 20.87 | E20: =(D20-6.75)/6 -> 2.3533333 | K20: =VLOOKUP(A20,IC_raw!$C$2:$E$111,3,FALSE) -> #N/A | L20: =VLOOKUP(A20,IC_raw!$C$2:$E$111,2,FALSE) -> #N/A
A21: P4T20 | B21: =C20 -> 45927.466 | C21: =B21+6/24 -> 45927.716 | D21: 21.15 | E21: =(D21-6.75)/6 -> 2.4 | K21: =VLOOKUP(A21,IC_raw!$C$2:$E$111,3,FALSE) -> #N/A | L21: =VLOOKUP(A21,IC_raw!$C$2:$E$111,2,FALSE) -> #N/A
A22: P4T21 | B22: =C21 -> 45927.716 | C22: =B22+6/24 -> 45927.966 | D22: 21.16 | E22: =(D22-6.75)/6 -> 2.4016667 | K22: =VLOOKUP(A22,IC_raw!$C$2:$E$111,3,FALSE) -> #N/A | L22: =VLOOKUP(A22,IC_raw!$C$2:$E$111,2,FALSE) -> #N/A
A23: P4T22 | B23: =C22 -> 45927.966 | C23: =B23+6/24 -> 45928.216 | D23: 20.93 | E23: =(D23-6.75)/6 -> 2.3633333 | K23: =VLOOKUP(A23,IC_raw!$C$2:$E$111,3,FALSE) -> #N/A | L23: =VLOOKUP(A23,IC_raw!$C$2:$E$111,2,FALSE) -> #N/A
A24: P4T23 | B24: =C23 -> 45928.216 | C24: =B24+6/24 -> 45928.466 | D24: 21.63 | E24: =(D24-6.75)/6 -> 2.48 | F24: 8.07 | G24: 583 | H24: 0.08 | I24: =0.5/62*14 -> 0.11290323 | K24: =VLOOKUP(A24,IC_raw!$C$2:$E$111,3,FALSE) -> 0.71 | L24: =VLOOKUP(A24,IC_raw!$C$2:$E$111,2,FALSE) -> 1.02
A25: P4T24 | B25: =C24 -> 45928.466 | C25: =B25+6/24 -> 45928.716 | D25: 21.45 | E25: =(D25-6.75)/6 -> 2.45 | K25: =VLOOKUP(A25,IC_raw!$C$2:$E$111,3,FALSE) -> #N/A | L25: =VLOOKUP(A25,IC_raw!$C$2:$E$111,2,FALSE) -> #N/A
A26: P4T25 | B26: =C25 -> 45928.716 | C26: =B26+6/24 -> 45928.966 | D26: 21.28 | E26: =(D26-6.75)/6 -> 2.4216667 | K26: =VLOOKUP(A26,IC_raw!$C$2:$E$111,3,FALSE) -> #N/A | L26: =VLOOKUP(A26,IC_raw!$C$2:$E$111,2,FALSE) -> #N/A
A27: P4T26 | B27: =C26 -> 45928.966 | C27: =B27+6/24 -> 45929.216 | D27: 20.92 | E27: =(D27-6.75)/6 -> 2.3616667 | K27: =VLOOKUP(A27,IC_raw!$C$2:$E$111,3,FALSE) -> #N/A | L27: =VLOOKUP(A27,IC_raw!$C$2:$E$111,2,FALSE) -> #N/A
A28: P4T27 | B28: =C27 -> 45929.216 | C28: =B28+6/24 -> 45929.466 | D28: 20.99 | E28: =(D28-6.75)/6 -> 2.3733333 | F28: 7.95 | G28: 635 | H28: 0.07 | I28: =0.5/62*14 -> 0.11290323 | K28: =VLOOKUP(A28,IC_raw!$C$2:$E$111,3,FALSE) -> 1.07 | L28: =VLOOKUP(A28,IC_raw!$C$2:$E$111,2,FALSE) -> 1 | M28: * cleaned pump tubing
A29: P4T28 | B29: =C28 -> 45929.466 | C29: =B29+6/24 -> 45929.716 | D29: 22.73 | E29: =(D29-6.75)/6 -> 2.6633333 | K29: =VLOOKUP(A29,IC_raw!$C$2:$E$111,3,FALSE) -> #N/A | L29: =VLOOKUP(A29,IC_raw!$C$2:$E$111,2,FALSE) -> #N/A
A30: P4T29 | B30: =C29 -> 45929.716 | C30: =B30+6/24 -> 45929.966 | D30: 23.03 | E30: =(D30-6.75)/6 -> 2.7133333 | K30: =VLOOKUP(A30,IC_raw!$C$2:$E$111,3,FALSE) -> #N/A | L30: =VLOOKUP(A30,IC_raw!$C$2:$E$111,2,FALSE) -> #N/A
A31: P4T30 | B31: =C30 -> 45929.966 | C31: =B31+6/24 -> 45930.216 | D31: 23.19 | E31: =(D31-6.75)/6 -> 2.74 | K31: =VLOOKUP(A31,IC_raw!$C$2:$E$111,3,FALSE) -> #N/A | L31: =VLOOKUP(A31,IC_raw!$C$2:$E$111,2,FALSE) -> #N/A
A32: P4T31 | B32: =C31 -> 45930.216 | C32: =B32+6/24 -> 45930.466 | D32: 23.2 | E32: =(D32-6.75)/6 -> 2.7416667 | K32: =VLOOKUP(A32,IC_raw!$C$2:$E$111,3,FALSE) -> #N/A | L32: =VLOOKUP(A32,IC_raw!$C$2:$E$111,2,FALSE) -> #N/A
A33: P4T32 | B33: =C32 -> 45930.466 | C33: =B33+6/24 -> 45930.716 | K33: =VLOOKUP(A33,IC_raw!$C$2:$E$111,3,FALSE) -> #N/A | L33: =VLOOKUP(A33,IC_raw!$C$2:$E$111,2,FALSE) -> #N/A
A34: P4T33 | B34: =C33 -> 45930.716 | C34: =B34+6/24 -> 45930.966 | D34: 21.38 | E34: =(D34-6.75)/6 -> 2.4383333 | K34: =VLOOKUP(A34,IC_raw!$C$2:$E$111,3,FALSE) -> #N/A | L34: =VLOOKUP(A34,IC_raw!$C$2:$E$111,2,FALSE) -> #N/A
A35: P4T34 | B35: =C34 -> 45930.966 | C35: =B35+6/24 -> 45931.216 | D35: 21.15 | E35: =(D35-6.75)/6 -> 2.4 | K35: =VLOOKUP(A35,IC_raw!$C$2:$E$111,3,FALSE) -> #N/A | L35: =VLOOKUP(A35,IC_raw!$C$2:$E$111,2,FALSE) -> #N/A
A36: P4T35 | B36: =C35 -> 45931.216 | C36: =B36+6/24 -> 45931.466 | D36: 21.08 | E36: =(D36-6.75)/6 -> 2.3883333 | F36: 7.86 | G36: 639 | K36: =VLOOKUP(A36,IC_raw!$C$2:$E$111,3,FALSE) -> 0 | L36: =VLOOKUP(A36,IC_raw!$C$2:$E$111,2,FALSE) -> 0
A37: P4T36 | B37: =C36 -> 45931.466 | C37: =B37+6/24 -> 45931.716 | D37: 18.92 | E37: =(D37-6.75)/6 -> 2.0283333 | K37: =VLOOKUP(A37,IC_raw!$C$2:$E$111,3,FALSE) -> #N/A | L37: =VLOOKUP(A37,IC_raw!$C$2:$E$111,2,FALSE) -> #N/A
A38: P4T37 | B38: =C37 -> 45931.716 | C38: =B38+6/24 -> 45931.966 | D38: 18.94 | E38: =(D38-6.75)/6 -> 2.0316667 | K38: =VLOOKUP(A38,IC_raw!$C$2:$E$111,3,FALSE) -> #N/A | L38: =VLOOKUP(A38,IC_raw!$C$2:$E$111,2,FALSE) -> #N/A
A39: P4T38 | B39: =C38 -> 45931.966 | C39: =B39+6/24 -> 45932.216 | D39: 18.33 | E39: =(D39-6.75)/6 -> 1.93 | K39: =VLOOKUP(A39,IC_raw!$C$2:$E$111,3,FALSE) -> #N/A | L39: =VLOOKUP(A39,IC_raw!$C$2:$E$111,2,FALSE) -> #N/A
A40: P4T39 | B40: =C39 -> 45932.216 | C40: =B40+6/24 -> 45932.466 | D40: 18.63 | E40: =(D40-6.75)/6 -> 1.98 | F40: 7.88 | G40: 608 | K40: =VLOOKUP(A40,IC_raw!$C$2:$E$111,3,FALSE) -> 0.85 | L40: =VLOOKUP(A40,IC_raw!$C$2:$E$111,2,FALSE) -> 0.98
...

Sheet IC_table
A1: sample

Sheet bromide_curve
A1: Sample | B1: start_time | C1: end_time | D1: weight | E1: flow_rate | F1: val1 | G1: br- [mmol/L] | H1: no3- [mgN/L] | I1: CI_no3 | J1: pH | K1: EC | L1: no2- [micromol/L] | M1: sample_for_IC | R1: Standard | S1: Value 1 | X1: concentration mM | Y1: volume (ml) | Z1: mass (mg) | AA1: molar mass | AB1: stock volume | AC1: agw volume
A2: B1T1 | B2: 45942.886 | C2: =B2+2/24 -> 45942.969 | D2: 10.65 | E2: =(D2-6.75)/2 -> 1.95 | F2: -33.5 | G2: =0.0076*EXP(0.0328*-F2) -> 0.02280428 | H2: 9.88 | I2: =0.5/62*14 -> 0.11290323 | R2: 2 | S2: -166.7 | T2: =-1*S2 -> 166.7 | X2: 10 | Y2: 50 | Z2: =AA2*X2*Y2/1000 -> 51.445 | AA2: 102.89
A3: B1T2 | B3: =C2 -> 45942.969 | C3: =B3+2/24 -> 45943.053 | D3: 10.55 | E3: =(D3-6.75)/2 -> 1.9 | F3: -34.3 | G3: =0.0076*EXP(0.0328*-F3) -> 0.023410584 | R3: 1 | S3: -149.2 | T3: =-1*S3 -> 149.2 | X3: 2 | Y3: 8 | AB3: =X3/X2*Y3 -> 1.6 | AC3: =Y3-AB3 -> 6.4
A4: B1T3 | B4: =C3 -> 45943.053 | C4: =B4+2/24 -> 45943.136 | D4: 10.56 | E4: =(D4-6.75)/2 -> 1.905 | F4: -34.4 | G4: =0.0076*EXP(0.0328*-F4) -> 0.023487497 | R4: 0.5 | S4: -131.2 | T4: =-1*S4 -> 131.2 | X4: 1 | Y4: 8 | AB4: =X4/$X$2*Y4 -> 0.8 | AC4: =Y4-AB4 -> 7.2
A5: B1T4 | B5: =C4 -> 45943.136 | C5: =B5+2/24 -> 45943.219 | D5: 10.64 | E5: =(D5-6.75)/2 -> 1.945 | F5: -70 | G5: =0.0076*EXP(0.0328*-F5) -> 0.075501177 | R5: 0.25 | S5: -113.3 | T5: =-1*S5 -> 113.3 | X5: 0.5 | Y5: 8 | AB5: =X5/$X$2*Y5 -> 0.4 | AC5: =Y5-AB5 -> 7.6
A6: B1T5 | B6: =C5 -> 45943.219 | C6: =B6+2/24 -> 45943.303 | D6: 10.61 | E6: =(D6-6.75)/2 -> 1.93 | F6: -122.8 | G6: =0.0076*EXP(0.0328*-F6) -> 0.42666034 | H6: 4.49 | I6: =0.5/62*14 -> 0.11290323 | R6: 0.1 | S6: -57.4 | T6: =-1*S6 -> 57.4 | X6: 0.25 | Y6: 8 | AB6: =X6/$X$2*Y6 -> 0.2 | AC6: =Y6-AB6 -> 7.8
A7: B1T6 | B7: =C6 -> 45943.303 | C7: =B7+2/24 -> 45943.386 | D7: 10.57 | E7: =(D7-6.75)/2 -> 1.91 | F7: -136.2 | G7: =0.0076*EXP(0.0328*-F7) -> 0.66216068 | R7: 0.05 | S7: -42.5 | T7: =-1*S7 -> 42.5 | X7: 0.1 | Y7: 4 | AB7: =X7/$X$2*Y7 -> 0.04 | AC7: =Y7-AB7 -> 3.96
A8: B1T7 | B8: =C7 -> 45943.386 | C8: =B8+2/24 -> 45943.469 | D8: 10.63 | E8: =(D8-6.75)/2 -> 1.94 | F8: -141.2 | G8: =0.0076*EXP(0.0328*-F8) -> 0.78016719 | R8: 0.01 | S8: -36.2 | T8: =-1*S8 -> 36.2 | AB8: =SUM(AB3:AB7) -> 3.04
A9: B1T8 | B9: =C8 -> 45943.469 | C9: =B9+2/24 -> 45943.553 | D9: 10.57 | E9: =(D9-6.75)/2 -> 1.91 | F9: -141.6 | G9: =0.0076*EXP(0.0328*-F9) -> 0.79047043
A10: B1T9 | B10: =C9 -> 45943.553 | C10: =B10+2/24 -> 45943.636 | D10: 10.58 | E10: =(D10-6.75)/2 -> 1.915 | F10: -142.7 | G10: =0.0076*EXP(0.0328*-F10) -> 0.81951135 | H10: 1.78 | I10: =0.5/62*14 -> 0.11290323
A11: B1T10 | B11: =C10 -> 45943.636 | C11: =B11+2/24 -> 45943.719 | D11: 10.71 | E11: =(D11-6.75)/2 -> 1.98 | F11: -143.2 | G11: =0.0076*EXP(0.0328*-F11) -> 0.83306215
A12: B1T11 | B12: =C11 -> 45943.719 | C12: =B12+2/24 -> 45943.803 | D12: 10.54 | E12: =(D12-6.75)/2 -> 1.895 | F12: =-143-2 -> -145 | G12: =0.0076*EXP(0.0328*-F12) -> 0.88372705 | H12: 1.72 | I12: =0.5/62*14 -> 0.11290323
A13: B1T12 | B13: =C12 -> 45943.803 | C13: =DATE(2025,10,13)+19.5/24 +6/24 -> 45944.062 | D13: 17.9 | E13: =(D13-6.75)/6 -> 1.8583333 | F13: -149.3 | G13: =0.0076*EXP(0.0328*-F13) -> 1.0175858
A14: B1T13 | B14: =C13 -> 45944.062 | C14: =B14+6/24 -> 45944.312 | D14: 18.15 | E14: =(D14-6.75)/6 -> 1.9
A15: B1T14 | B15: =C14 -> 45944.312 | C15: =B15+6/24 -> 45944.562 | D15: 18.2 | E15: =(D15-6.75)/6 -> 1.9083333 | H15: 0.871 | I15: =0.5/62*14 -> 0.11290323 | J15: 8 | K15: 827
A16: B2T1 | B16: 45942.886 | C16: =B16+2/24 -> 45942.969 | D16: 10.67 | E16: =(D16-6.75)/2 -> 1.96 | F16: -40.6 | G16: =0.0076*EXP(0.0328*-F16) -> 0.028784247 | H16: 7.4 | I16: =0.5/62*14 -> 0.11290323
A17: B2T2 | B17: =C16 -> 45942.969 | C17: =B17+2/24 -> 45943.053 | D17: 11.05 | E17: =(D17-6.75)/2 -> 2.15 | F17: -40.2 | G17: =0.0076*EXP(0.0328*-F17) -> 0.028409064
A18: B2T3 | B18: =C17 -> 45943.053 | C18: =B18+2/24 -> 45943.136 | D18: 10.63 | E18: =(D18-6.75)/2 -> 1.94 | F18: -55.4 | G18: =0.0076*EXP(0.0328*-F18) -> 0.046771229
A19: B2T4 | B19: =C18 -> 45943.136 | C19: =B19+2/24 -> 45943.219 | D19: 10.8 | E19: =(D19-6.75)/2 -> 2.025 | F19: -104.9 | G19: =0.0076*EXP(0.0328*-F19) -> 0.2371916
A20: B2T5 | B20: =C19 -> 45943.219 | C20: =B20+2/24 -> 45943.303 | D20: 10.66 | E20: =(D20-6.75)/2 -> 1.955 | F20: -131.4 | G20: =0.0076*EXP(0.0328*-F20) -> 0.56570246 | H20: 2.32 | I20: =0.5/62*14 -> 0.11290323
A21: B2T6 | B21: =C20 -> 45943.303 | C21: =B21+2/24 -> 45943.386 | D21: 10.83 | E21: =(D21-6.75)/2 -> 2.04 | F21: -136.7 | G21: =0.0076*EXP(0.0328*-F21) -> 0.67310965
A22: B2T7 | B22: =C21 -> 45943.386 | C22: =B22+2/24 -> 45943.469 | D22: 10.88 | E22: =(D22-6.75)/2 -> 2.065 | F22: -141.6 | G22: =0.0076*EXP(0.0328*-F22) -> 0.79047043
A23: B2T8 | B23: =C22 -> 45943.469 | C23: =B23+2/24 -> 45943.553 | D23: 10.63 | E23: =(D23-6.75)/2 -> 1.94 | F23: -143.8 | G23: =0.0076*EXP(0.0328*-F23) -> 0.8496192
A24: B2T9 | B24: =C23 -> 45943.553 | C24: =B24+2/24 -> 45943.636 | D24: 9.5 | E24: =(D24-6.75)/2 -> 1.375 | F24: -145.8 | G24: =0.0076*EXP(0.0328*-F24) -> 0.90722297 | H24: 0.868 | I24: =0.5/62*14 -> 0.11290323
A25: B2T10 | B25: =C24 -> 45943.636 | C25: =B25+2/24 -> 45943.719 | D25: 11.24 | E25: =(D25-6.75)/2 -> 2.245 | F25: -145.7 | G25: =0.0076*EXP(0.0328*-F25) -> 0.90425215
A26: B2T11 | B26: =C25 -> 45943.719 | C26: =B26+2/24 -> 45943.803 | D26: 10.76 | E26: =(D26-6.75)/2 -> 2.005 | F26: -144.2 | G26: =0.0076*EXP(0.0328*-F26) -> 0.86083965 | H26: 0.392 | I26: =0.5/62*14 -> 0.11290323
A27: B2T12 | B27: =C26 -> 45943.803 | C27: =DATE(2025,10,13)+19.5/24 +6/24 -> 45944.062 | D27: 18.94 | E27: =(D27-6.75)/6 -> 2.0316667 | F27: -145.1 | G27: =0.0076*EXP(0.0328*-F27) -> 0.88663043
A28: B2T13 | B28: =C27 -> 45944.062 | C28: =B28+6/24 -> 45944.312 | D28: 18.85 | E28: =(D28-6.75)/6 -> 2.0166667
A29: B2T14 | B29: =C28 -> 45944.312 | C29: =B29+6/24 -> 45944.562 | D29: 18.78 | E29: =(D29-6.75)/6 -> 2.005 | H29: 0.254 | I29: =0.5/62*14 -> 0.11290323 | J29: 8.1 | K29: 828
A30: B3T1 | B30: 45942.886 | C30: =B30+2/24 -> 45942.969 | D30: 10.81 | E30: =(D30-6.75)/2 -> 2.03 | F30: -43.4 | G30: =0.0076*EXP(0.0328*-F30) -> 0.031552987 | H30: 8.42 | I30: =0.5/62*14 -> 0.11290323
A31: B3T2 | B31: =C30 -> 45942.969 | C31: =B31+2/24 -> 45943.053 | D31: 10.67 | E31: =(D31-6.75)/2 -> 1.96 | F31: -46.9 | G31: =0.0076*EXP(0.0328*-F31) -> 0.035391379
A32: B3T3 | B32: =C31 -> 45943.053 | C32: =B32+2/24 -> 45943.136 | D32: 10.8 | E32: =(D32-6.75)/2 -> 2.025 | F32: -59.9 | G32: =0.0076*EXP(0.0328*-F32) -> 0.054210155
A33: B3T4 | B33: =C32 -> 45943.136 | C33: =B33+2/24 -> 45943.219 | D33: 10.83 | E33: =(D33-6.75)/2 -> 2.04 | F33: -107.7 | G33: =0.0076*EXP(0.0328*-F33) -> 0.26000692
A34: B3T5 | B34: =C33 -> 45943.219 | C34: =B34+2/24 -> 45943.303 | D34: 10.78 | E34: =(D34-6.75)/2 -> 2.015 | F34: -133.6 | G34: =0.0076*EXP(0.0328*-F34) -> 0.60803245 | H34: 1.79 | I34: =0.5/62*14 -> 0.11290323
A35: B3T6 | B35: =C34 -> 45943.303 | C35: =B35+2/24 -> 45943.386 | D35: 10.66 | E35: =(D35-6.75)/2 -> 1.955 | F35: -139.1 | G35: =0.0076*EXP(0.0328*-F35) -> 0.72823824
A36: B3T7 | B36: =C35 -> 45943.386 | C36: =B36+2/24 -> 45943.469 | D36: 10.83 | E36: =(D36-6.75)/2 -> 2.04 | F36: -141.6 | G36: =0.0076*EXP(0.0328*-F36) -> 0.79047043
A37: B3T8 | B37: =C36 -> 45943.469 | C37: =B37+2/24 -> 45943.553 | D37: 10.67 | E37: =(D37-6.75)/2 -> 1.96 | F37: -144.1 | G37: =0.0076*EXP(0.0328*-F37) -> 0.85802072
A38: B3T9 | B38: =C37 -> 45943.553 | C38: =B38+2/24 -> 45943.636 | D38: 10.7 | E38: =(D38-6.75)/2 -> 1.975 | F38: -146.5 | G38: =0.0076*EXP(0.0328*-F38) -> 0.92829377 | H38: 1.47 | I38: =0.5/62*14 -> 0.11290323
A39: B3T10 | B39: =C38 -> 45943.636 | C39: =B39+2/24 -> 45943.719 | D39: 9.98 | E39: =(D39-6.75)/2 -> 1.615 | F39: -146 | G39: =0.0076*EXP(0.0328*-F39) -> 0.91319391
A40: B3T11 | B40: =C39 -> 45943.719 | C40: =B40+2/24 -> 45943.803 | D40: 10.95 | E40: =(D40-6.75)/2 -> 2.1 | F40: -144.5 | G40: =0.0076*EXP(0.0328*-F40) -> 0.86935212 | H40: 1.36 | I40: =0.5/62*14 -> 0.11290323
...

Sheet bromide_curve_v2
A1: Sample | B1: start_time | C1: end_time | D1: weight | E1: flow_rate | F1: val1 | G1: br- [mmol/L] | H1: no3- [mgN/L] | I1: CI_no3 | J1: pH | K1: EC | L1: no3_mg_L | M1: sample_for_IC | R1: Standard | S1: Value 1 | X1: concentration mM | Y1: volume (ml) | Z1: mass (mg) | AA1: molar mass | AB1: stock volume | AC1: agw volume
A2: B1T1 | B2: 45942.886 | C2: =B2+2/24 -> 45942.969 | D2: 10.65 | E2: =(D2-6.75)/2 -> 1.95 | H2: 9.88 | I2: =0.5/62*14 -> 0.11290323 | L2: =VLOOKUP(A2,IC_raw!$C$2:$E$111,2,FALSE) -> #N/A | R2: 2 | S2: -161.3 | T2: =-1*S2 -> 161.3 | X2: 10 | Y2: 50 | Z2: =AA2*X2*Y2/1000 -> 51.445 | AA2: 102.89
A3: B1T2 | B3: =C2 -> 45942.969 | C3: =B3+2/24 -> 45943.053 | D3: 10.55 | E3: =(D3-6.75)/2 -> 1.9 | L3: =VLOOKUP(A3,IC_raw!$C$2:$E$111,2,FALSE) -> 0 | R3: 1 | S3: -143.6 | T3: =-1*S3 -> 143.6 | X3: 2 | Y3: 8 | AB3: =X3/X2*Y3 -> 1.6 | AC3: =Y3-AB3 -> 6.4
A4: B1T3 | B4: =C3 -> 45943.053 | C4: =B4+2/24 -> 45943.136 | D4: 10.56 | E4: =(D4-6.75)/2 -> 1.905 | F4: -53 | G4: =0.0074*EXP(0.0341*-F4) -> 0.045095389 | L4: =VLOOKUP(A4,IC_raw!$C$2:$E$111,2,FALSE) -> #N/A | R4: 0.5 | S4: -125.2 | T4: =-1*S4 -> 125.2 | X4: 1 | Y4: 8 | AB4: =X4/$X$2*Y4 -> 0.8 | AC4: =Y4-AB4 -> 7.2
A5: B1T4 | B5: =C4 -> 45943.136 | C5: =B5+2/24 -> 45943.219 | D5: 10.64 | E5: =(D5-6.75)/2 -> 1.945 | F5: -76.4 | G5: =0.0074*EXP(0.0341*-F5) -> 0.1001551 | L5: =VLOOKUP(A5,IC_raw!$C$2:$E$111,2,FALSE) -> #N/A | R5: 0.25 | S5: -106.5 | T5: =-1*S5 -> 106.5 | X5: 0.5 | Y5: 8 | AB5: =X5/$X$2*Y5 -> 0.4 | AC5: =Y5-AB5 -> 7.6
A6: B1T5 | B6: =C5 -> 45943.219 | C6: =B6+2/24 -> 45943.303 | D6: 10.61 | E6: =(D6-6.75)/2 -> 1.93 | F6: -121.3 | G6: =0.0074*EXP(0.0341*-F6) -> 0.46303841 | H6: 4.49 | I6: =0.5/62*14 -> 0.11290323 | L6: =VLOOKUP(A6,IC_raw!$C$2:$E$111,2,FALSE) -> #N/A | R6: 0.1 | S6: -47.1 | T6: =-1*S6 -> 47.1 | X6: 0.25 | Y6: 8 | AB6: =X6/$X$2*Y6 -> 0.2 | AC6: =Y6-AB6 -> 7.8
A7: B1T6 | B7: =C6 -> 45943.303 | C7: =B7+2/24 -> 45943.386 | D7: 10.57 | E7: =(D7-6.75)/2 -> 1.91 | L7: =VLOOKUP(A7,IC_raw!$C$2:$E$111,2,FALSE) -> 57.07 | R7: 0.05 | S7: -45.8 | T7: =-1*S7 -> 45.8 | X7: 0.1 | Y7: 4 | AB7: =X7/$X$2*Y7 -> 0.04 | AC7: =Y7-AB7 -> 3.96
A8: B1T7 | B8: =C7 -> 45943.386 | C8: =B8+2/24 -> 45943.469 | D8: 10.63 | E8: =(D8-6.75)/2 -> 1.94 | F8: -140.4 | G8: =0.0074*EXP(0.0341*-F8) -> 0.88813166 | L8: =VLOOKUP(A8,IC_raw!$C$2:$E$111,2,FALSE) -> #N/A | R8: 0.01 | S8: -44.8 | T8: =-1*S8 -> 44.8 | AB8: =SUM(AB3:AB7) -> 3.04
A9: B1T8 | B9: =C8 -> 45943.469 | C9: =B9+2/24 -> 45943.553 | D9: 10.57 | E9: =(D9-6.75)/2 -> 1.91 | F9: -143.5 | G9: =0.0074*EXP(0.0341*-F9) -> 0.98715789 | L9: =VLOOKUP(A9,IC_raw!$C$2:$E$111,2,FALSE) -> #N/A
A10: B1T9 | B10: =C9 -> 45943.553 | C10: =B10+2/24 -> 45943.636 | D10: 10.58 | E10: =(D10-6.75)/2 -> 1.915 | F10: -144 | G10: =0.0074*EXP(0.0341*-F10) -> 1.0041332 | H10: 1.78 | I10: =0.5/62*14 -> 0.11290323 | L10: =VLOOKUP(A10,IC_raw!$C$2:$E$111,2,FALSE) -> #N/A
A11: B1T10 | B11: =C10 -> 45943.636 | C11: =B11+2/24 -> 45943.719 | D11: 10.71 | E11: =(D11-6.75)/2 -> 1.98 | F11: -144.5 | G11: =0.0074*EXP(0.0341*-F11) -> 1.0214005 | L11: =VLOOKUP(A11,IC_raw!$C$2:$E$111,2,FALSE) -> 12.24
A12: B1T11 | B12: =C11 -> 45943.719 | C12: =B12+2/24 -> 45943.803 | D12: 10.54 | E12: =(D12-6.75)/2 -> 1.895 | H12: 1.72 | I12: =0.5/62*14 -> 0.11290323 | L12: =VLOOKUP(A12,IC_raw!$C$2:$E$111,2,FALSE) -> #N/A
A13: B1T12 | B13: =C12 -> 45943.803 | C13: =DATE(2025,10,13)+19.5/24 +6/24 -> 45944.062 | D13: 17.9 | E13: =(D13-6.75)/6 -> 1.8583333 | L13: =VLOOKUP(A13,IC_raw!$C$2:$E$111,2,FALSE) -> #N/A
A14: B1T13 | B14: =C13 -> 45944.062 | C14: =B14+6/24 -> 45944.312 | D14: 18.15 | E14: =(D14-6.75)/6 -> 1.9 | L14: =VLOOKUP(A14,IC_raw!$C$2:$E$111,2,FALSE) -> #N/A
A15: B1T14 | B15: =C14 -> 45944.312 | C15: =B15+6/24 -> 45944.562 | D15: 18.2 | E15: =(D15-6.75)/6 -> 1.9083333 | H15: 0.871 | I15: =0.5/62*14 -> 0.11290323 | J15: 8 | K15: 827 | L15: =VLOOKUP(A15,IC_raw!$C$2:$E$111,2,FALSE) -> 10.71
A16: B1T16 | B16: 45945.441 | C16: 45945.601 | D16: 14.33 | E16: =(D16-6.75)/4 -> 1.895 | H16: 1.65 | I16: =0.5/62*14 -> 0.11290323 | L16: =VLOOKUP(A16,IC_raw!$C$2:$E$111,2,FALSE) -> 12.2
A17: B2T1 | B17: 45942.886 | C17: =B17+2/24 -> 45942.969 | D17: 10.67 | E17: =(D17-6.75)/2 -> 1.96 | H17: 7.4 | I17: =0.5/62*14 -> 0.11290323 | L17: =VLOOKUP(A17,IC_raw!$C$2:$E$111,2,FALSE) -> #N/A
A18: B2T2 | B18: =C17 -> 45942.969 | C18: =B18+2/24 -> 45943.053 | D18: 11.05 | E18: =(D18-6.75)/2 -> 2.15 | L18: =VLOOKUP(A18,IC_raw!$C$2:$E$111,2,FALSE) -> 33.83
A19: B2T3 | B19: =C18 -> 45943.053 | C19: =B19+2/24 -> 45943.136 | D19: 10.63 | E19: =(D19-6.75)/2 -> 1.94 | F19: -75.4 | G19: =0.0074*EXP(0.0341*-F19) -> 0.096797387 | L19: =VLOOKUP(A19,IC_raw!$C$2:$E$111,2,FALSE) -> 0
A20: B2T4 | B20: =C19 -> 45943.136 | C20: =B20+2/24 -> 45943.219 | D20: 10.8 | E20: =(D20-6.75)/2 -> 2.025 | F20: -107.8 | G20: =0.0074*EXP(0.0341*-F20) -> 0.29220628 | L20: =VLOOKUP(A20,IC_raw!$C$2:$E$111,2,FALSE) -> #N/A
A21: B2T5 | B21: =C20 -> 45943.219 | C21: =B21+2/24 -> 45943.303 | D21: 10.66 | E21: =(D21-6.75)/2 -> 1.955 | F21: -127 | G21: =0.0074*EXP(0.0341*-F21) -> 0.56238125 | H21: 2.32 | I21: =0.5/62*14 -> 0.11290323 | L21: =VLOOKUP(A21,IC_raw!$C$2:$E$111,2,FALSE) -> #N/A
A22: B2T6 | B22: =C21 -> 45943.303 | C22: =B22+2/24 -> 45943.386 | D22: 10.83 | E22: =(D22-6.75)/2 -> 2.04 | L22: =VLOOKUP(A22,IC_raw!$C$2:$E$111,2,FALSE) -> 7.55
A23: B2T7 | B23: =C22 -> 45943.386 | C23: =B23+2/24 -> 45943.469 | D23: 10.88 | E23: =(D23-6.75)/2 -> 2.065 | F23: -140.6 | G23: =0.0074*EXP(0.0341*-F23) -> 0.89420942 | L23: =VLOOKUP(A23,IC_raw!$C$2:$E$111,2,FALSE) -> #N/A
A24: B2T8 | B24: =C23 -> 45943.469 | C24: =B24+2/24 -> 45943.553 | D24: 10.63 | E24: =(D24-6.75)/2 -> 1.94 | F24: -146.7 | G24: =0.0074*EXP(0.0341*-F24) -> 1.1009734 | L24: =VLOOKUP(A24,IC_raw!$C$2:$E$111,2,FALSE) -> #N/A
A25: B2T9 | B25: =C24 -> 45943.553 | C25: =B25+2/24 -> 45943.636 | D25: 9.5 | E25: =(D25-6.75)/2 -> 1.375 | H25: 0.868 | I25: =0.5/62*14 -> 0.11290323 | L25: =VLOOKUP(A25,IC_raw!$C$2:$E$111,2,FALSE) -> #N/A
A26: B2T10 | B26: =C25 -> 45943.636 | C26: =B26+2/24 -> 45943.719 | D26: 11.24 | E26: =(D26-6.75)/2 -> 2.245 | L26: =VLOOKUP(A26,IC_raw!$C$2:$E$111,2,FALSE) -> 5.01
A27: B2T11 | B27: =C26 -> 45943.719 | C27: =B27+2/24 -> 45943.803 | D27: 10.76 | E27: =(D27-6.75)/2 -> 2.005 | F27: -143.6 | G27: =0.0074*EXP(0.0341*-F27) -> 0.99052985 | H27: 0.392 | I27: =0.5/62*14 -> 0.11290323 | L27: =VLOOKUP(A27,IC_raw!$C$2:$E$111,2,FALSE) -> #N/A
A28: B2T12 | B28: =C27 -> 45943.803 | C28: =DATE(2025,10,13)+19.5/24 +6/24 -> 45944.062 | D28: 18.94 | E28: =(D28-6.75)/6 -> 2.0316667 | F28: -144.6 | G28: =0.0074*EXP(0.0341*-F28) -> 1.0248894 | L28: =VLOOKUP(A28,IC_raw!$C$2:$E$111,2,FALSE) -> #N/A
A29: B2T13 | B29: =C28 -> 45944.062 | C29: =B29+6/24 -> 45944.312 | D29: 18.85 | E29: =(D29-6.75)/6 -> 2.0166667 | L29: =VLOOKUP(A29,IC_raw!$C$2:$E$111,2,FALSE) -> #N/A
A30: B2T14 | B30: =C29 -> 45944.312 | C30: =B30+6/24 -> 45944.562 | D30: 18.78 | E30: =(D30-6.75)/6 -> 2.005 | H30: 0.254 | I30: =0.5/62*14 -> 0.11290323 | J30: 8.1 | K30: 828 | L30: =VLOOKUP(A30,IC_raw!$C$2:$E$111,2,FALSE) -> 2.43
A31: B2T16 | B31: 45945.441 | C31: 45945.601 | D31: 14.7 | E31: =(D31-6.75)/4 -> 1.9875 | H31: 0.32 | I31: =0.5/62*14 -> 0.11290323 | L31: =VLOOKUP(A31,IC_raw!$C$2:$E$111,2,FALSE) -> 3.92
A32: B3T1 | B32: 45942.886 | C32: =B32+2/24 -> 45942.969 | D32: 10.81 | E32: =(D32-6.75)/2 -> 2.03 | H32: 8.42 | I32: =0.5/62*14 -> 0.11290323 | L32: =VLOOKUP(A32,IC_raw!$C$2:$E$111,2,FALSE) -> #N/A
A33: B3T2 | B33: =C32 -> 45942.969 | C33: =B33+2/24 -> 45943.053 | D33: 10.67 | E33: =(D33-6.75)/2 -> 1.96 | L33: =VLOOKUP(A33,IC_raw!$C$2:$E$111,2,FALSE) -> 38.94
A34: B3T3 | B34: =C33 -> 45943.053 | C34: =B34+2/24 -> 45943.136 | D34: 10.8 | E34: =(D34-6.75)/2 -> 2.025 | F34: -67.5 | G34: =0.0074*EXP(0.0341*-F34) -> 0.073938229 | L34: =VLOOKUP(A34,IC_raw!$C$2:$E$111,2,FALSE) -> #N/A
A35: B3T4 | B35: =C34 -> 45943.136 | C35: =B35+2/24 -> 45943.219 | D35: 10.83 | E35: =(D35-6.75)/2 -> 2.04 | F35: -108.5 | G35: =0.0074*EXP(0.0341*-F35) -> 0.29926516 | L35: =VLOOKUP(A35,IC_raw!$C$2:$E$111,2,FALSE) -> #N/A
A36: B3T5 | B36: =C35 -> 45943.219 | C36: =B36+2/24 -> 45943.303 | D36: 10.78 | E36: =(D36-6.75)/2 -> 2.015 | F36: -131.3 | G36: =0.0074*EXP(0.0341*-F36) -> 0.65119556 | H36: 1.79 | I36: =0.5/62*14 -> 0.11290323 | L36: =VLOOKUP(A36,IC_raw!$C$2:$E$111,2,FALSE) -> #N/A
A37: B3T6 | B37: =C36 -> 45943.303 | C37: =B37+2/24 -> 45943.386 | D37: 10.66 | E37: =(D37-6.75)/2 -> 1.955 | L37: =VLOOKUP(A37,IC_raw!$C$2:$E$111,2,FALSE) -> 11.54
A38: B3T7 | B38: =C37 -> 45943.386 | C38: =B38+2/24 -> 45943.469 | D38: 10.83 | E38: =(D38-6.75)/2 -> 2.04 | F38: -141.3 | G38: =0.0074*EXP(0.0341*-F38) -> 0.91581099 | L38: =VLOOKUP(A38,IC_raw!$C$2:$E$111,2,FALSE) -> #N/A
A39: B3T8 | B39: =C38 -> 45943.469 | C39: =B39+2/24 -> 45943.553 | D39: 10.67 | E39: =(D39-6.75)/2 -> 1.96 | F39: -142.8 | G39: =0.0074*EXP(0.0341*-F39) -> 0.96387344 | L39: =VLOOKUP(A39,IC_raw!$C$2:$E$111,2,FALSE) -> #N/A
A40: B3T9 | B40: =C39 -> 45943.553 | C40: =B40+2/24 -> 45943.636 | D40: 10.7 | E40: =(D40-6.75)/2 -> 1.975 | H40: 1.47 | I40: =0.5/62*14 -> 0.11290323 | L40: =VLOOKUP(A40,IC_raw!$C$2:$E$111,2,FALSE) -> #N/A
...

Sheet fe_total
A1: Sample | B1: time_in | C1: time_out | D1: reading | E1: conc_microm | G1: Standard | H1: Value 1 | I1: Value 2 | L1: obs: hacl 50, sample 50, fer 100
A2: P1F1 | B2: 45924.667 | C2: 45924.708 | D2: 0.087 | E2: =282.18*D2-28.951 -> -4.40134 | G2: 10 | H2: 0.129
A3: P2F1 | B3: 45924.667 | C3: 45924.708 | D3: 0.094 | E3: =282.18*D3-28.951 -> -2.42608 | G3: 25 | H3: 0.198
A4: P3F1 | B4: 45924.667 | C4: 45924.708 | D4: 0.09 | E4: =282.18*D4-28.951 -> -3.5548 | G4: 50 | H4: 0.287
A5: P4F1 | B5: 45924.667 | C5: 45924.708 | D5: 0.089 | E5: =282.18*D5-28.951 -> -3.83698 | G5: 100 | H5: 0.452
A6: P1F2 | B6: 45926.601 | C6: 45926.642 | D6: 0.096 | E6: =282.18*D6-28.951 -> -1.86172
A7: P2F2 | B7: 45926.601 | C7: 45926.642 | D7: 0.096 | E7: =282.18*D7-28.951 -> -1.86172
A8: P3F2 | B8: 45926.601 | C8: 45926.642 | D8: 0.097 | E8: =282.18*D8-28.951 -> -1.57954
A9: P4F2 | B9: 45926.601 | C9: 45926.642 | D9: 0.094 | E9: =282.18*D9-28.951 -> -2.42608
A10: P1F3 | B10: 45931.552 | C10: 45931.594 | D10: 0.09 | E10: =282.18*D10-28.951 -> -3.5548
A11: P2F3 | B11: 45931.552 | C11: 45931.594 | D11: 0.088 | E11: =282.18*D11-28.951 -> -4.11916
A12: P3F3 | B12: 45931.552 | C12: 45931.594 | D12: 0.094 | E12: =282.18*D12-28.951 -> -2.42608
A13: P4F3 | B13: 45931.552 | C13: 45931.594 | D13: 0.095 | E13: =282.18*D13-28.951 -> -2.1439
A14: P1F4 | B14: 45936.594 | C14: 45936.635 | D14: 0.09 | E14: =282.18*D14-28.951 -> -3.5548
A15: P2F4 | B15: 45936.594 | C15: 45936.635 | D15: 0.091 | E15: =282.18*D15-28.951 -> -3.27262
A16: P3F4 | B16: 45936.594 | C16: 45936.635 | D16: 0.094 | E16: =282.18*D16-28.951 -> -2.42608
A17: P4F4 | B17: 45936.594 | C17: 45936.635 | D17: 0.162 | E17: =282.18*D17-28.951 -> 16.76216

Sheet hs
A1: Sample | B1: time_in | C1: time_out | D1: volume | E1: flow_rate | F1: pH | G1: EC | H1: conc

Sheet standard_curve_no2
A1: date | B1: column/batch | C1: Sample | D1: val1 | E1: dil | F1: no2- [micromol/L] | G1: Standard | H1: Value 1 | I1: Value 2 | J1: Avg
A2: 12.09 | B2: P1 | C2: =_xlfn.CONCAT("F",B2,"-",A2) -> FP1-12.09 | D2: 0.314 | E2: 1 | F2: =($J$11*AVERAGE(D2:D2)+$J$12)*E2 -> 16.045509 | G2: 50 | H2: 0.873 | I2: 0.902 | J2: =AVERAGE(H2:I2) -> 0.8875
A3: 12.09 | B3: control | C3: =_xlfn.CONCAT("F",B3,"-",A3) -> Fcontrol-12.09 | D3: 0.227 | E3: 1 | F3: =($J$11*AVERAGE(D3:D3)+$J$12)*E3 -> 10.929784 | G3: 40 | H3: 0.715 | I3: 0.74 | J3: =AVERAGE(H3:I3) -> 0.7275
A4: 12.09 | B4: 19-20B | C4: =_xlfn.CONCAT("F",B4,"-",A4) -> F19-20B-12.09 | D4: 0.205 | E4: 1 | F4: =($J$11*AVERAGE(D4:D4)+$J$12)*E4 -> 9.6361525 | G4: 30 | H4: 0.575 | I4: 0.474 | J4: =AVERAGE(H4:I4) -> 0.5245
A5: 12.09 | B5: 13-14A | C5: =_xlfn.CONCAT("F",B5,"-",A5) -> F13-14A-12.09 | D5: 0.059 | E5: 1 | F5: =($J$11*AVERAGE(D5:D5)+$J$12)*E5 -> 1.0511424 | G5: 20 | H5: 0.399 | I5: 0.413 | J5: =AVERAGE(H5:I5) -> 0.406
A6: 12.09 | B6: 13-14B | C6: =_xlfn.CONCAT("F",B6,"-",A6) -> F13-14B-12.09 | D6: 0.172 | E6: 1 | F6: =($J$11*AVERAGE(D6:D6)+$J$12)*E6 -> 7.695705 | G6: 10 | H6: 0.226 | I6: 0.229 | J6: =AVERAGE(H6:I6) -> 0.2275
A7: 12.09 | B7: 17-18B | C7: =_xlfn.CONCAT("F",B7,"-",A7) -> F17-18B-12.09 | D7: 0.069 | E7: 1 | F7: =($J$11*AVERAGE(D7:D7)+$J$12)*E7 -> 1.6391568 | G7: 5 | H7: 0.128 | I7: 0.13 | J7: =AVERAGE(H7:I7) -> 0.129
A8: 12.09 | B8: 16-17B | C8: =_xlfn.CONCAT("F",B8,"-",A8) -> F16-17B-12.09 | D8: 0.099 | E8: 1 | F8: =($J$11*AVERAGE(D8:D8)+$J$12)*E8 -> 3.4032 | G8: 2 | H8: 0.07 | I8: 0.068 | J8: =AVERAGE(H8:I8) -> 0.069
A9: 12.09 | B9: 17-18A | C9: =_xlfn.CONCAT("F",B9,"-",A9) -> F17-18A-12.09 | D9: 0.087 | E9: 1 | F9: =($J$11*AVERAGE(D9:D9)+$J$12)*E9 -> 2.6975827 | G9: 1 | H9: 0.051 | I9: 0.039 | J9: =AVERAGE(H9:I9) -> 0.045
A10: 12.09 | B10: 18-19 | C10: =_xlfn.CONCAT("F",B10,"-",A10) -> F18-19-12.09 | D10: 0.09 | E10: 1 | F10: =($J$11*AVERAGE(D10:D10)+$J$12)*E10 -> 2.8739871
A11: 12.09 | B11: 19-20A | C11: =_xlfn.CONCAT("F",B11,"-",A11) -> F19-20A-12.09 | D11: 0.058 | E11: 1 | F11: =($J$11*AVERAGE(D11:D11)+$J$12)*E11 -> 0.99234101 | I11: slope: | J11: =SLOPE(G2:G9,J2:J9) -> 58.801439
A12: 12.09 | B12: 16-17A | C12: =_xlfn.CONCAT("F",B12,"-",A12) -> F16-17A-12.09 | D12: 0.167 | E12: 1 | F12: =($J$11*AVERAGE(D12:D12)+$J$12)*E12 -> 7.4016978 | I12: intercept: | J12: =INTERCEPT(G2:G9,J2:J9) -> -2.4181424
A13: 14.09 | B13: P1 | C13: =_xlfn.CONCAT("F",B13,"-",A13) -> FP1-14.09 | D13: 0.642 | E13: 4 | F13: =($J$11*AVERAGE(D13:D13)+$J$12)*E13 -> 141.32953
C14: P1T0 | D14: 0.126 | E14: 4 | F14: =($J$11*AVERAGE(D14:D14)+$J$12)*E14 -> 19.963355
C15: P1T3 | D15: 0.198 | E15: 4 | F15: =($J$11*AVERAGE(D15:D15)+$J$12)*E15 -> 36.89817
C16: P1T8 | D16: 0.19 | E16: 4 | F16: =($J$11*AVERAGE(D16:D16)+$J$12)*E16 -> 35.016524
C17: P1T15 | D17: 0.179 | E17: 4 | F17: =($J$11*AVERAGE(D17:D17)+$J$12)*E17 -> 32.42926
C18: P1T23 | D18: 0.197 | E18: 4 | F18: =($J$11*AVERAGE(D18:D18)+$J$12)*E18 -> 36.662964
C19: P1T27 | D19: 0.183 | E19: 4 | F19: =($J$11*AVERAGE(D19:D19)+$J$12)*E19 -> 33.370083
C20: P2T0 | D20: 0.035 | E20: 4 | F20: =($J$11*AVERAGE(D20:D20)+$J$12)*E20 -> -1.4403683
C21: P2T3 | D21: 0.814 | E21: 20 | F21: =($J$11*AVERAGE(D21:D21)+$J$12)*E21 -> 908.92458
C22: P2T8 | D22: 0.683 | E22: 20 | F22: =($J$11*AVERAGE(D22:D22)+$J$12)*E22 -> 754.86481
C23: P2T15 | D23: 0.51 | E23: 10 | F23: =($J$11*AVERAGE(D23:D23)+$J$12)*E23 -> 275.70591
C24: P2T23 | D24: 0.382 | E24: 10 | F24: =($J$11*AVERAGE(D24:D24)+$J$12)*E24 -> 200.44007
C25: P2T26 | D25: 0.31 | E25: 10 | F25: =($J$11*AVERAGE(D25:D25)+$J$12)*E25 -> 158.10304
... C81: P4T80 | D81: 0.038 | E81: 1 | F81: =($J$11*AVERAGE(D81:D81)+$J$12)*E81 -> -0.18368777

Sheet fe_plate_1
A1: time_label | B1: column | C1: name | D1: val1 | E1: val2 | F1: obs | G1: fe2+ [micromol/L] | I1: Standard | J1: Value 1 | K1: Value 2 | L1: Value 3 | M1: Avg
C2: P1F1 | D2: 0.039 | G2: =AVERAGE(D2:E2)*$K$11 + $K$12 -> -3.2082434 | I2: 1000 | J2: 1.556 | K2: 1.548 | M2: =AVERAGE(J2:L2) -> 1.552
